Workbook

Sheet 说明
B1: 说明
B3: 银行名称区 | E3: 数字区 | H3: 测试数据表
B5: 样式 | C5: 含义 | E5: 样式 | F5: 含义 | H5: 名称 | I5: 含义
B6: 名称填充色 | C6: 健康的。未填充颜色 | E6: 数字填充色 | F6: 未变化的 | H6: 形如右边： | I6: “我设定的Bank之过程-20220307”、“我设定的Bank Interbank之过程-20220306”等数据表内容，分别表示各银行主要变量变动情况、和银行间主要变量变动情况。
B7: 名称填充色 | C7: 资不抵债相关的。 | E7: 数字填充色 | F7: 变化的，因为外部冲击 | H7: XX之过程-参数Y | I7: 银行变量或者银行间主要变量变动过程，当初始设定参数Y时。
B8: 名称填充色 | C8: 流动性短缺相关的。 | E8: 数字填充色 | F8: 变化的，因为银行间违约冲击
B9: 名称填充色 | C9: 破产相关的。 | E9: 数字填充色 | F9: 变化的，因为流动性短缺银行之银行间流动挤兑冲击
B10: 名称填充色 | C10: 退出的。 | E10: 数字填充色 | F10: 变化的，因为破产银行之银行间流动挤兑冲击
E11: 数字填充色 | F11: 变化的，因为破产银行清算影响
E12: 数字填充色 | F12: 变化的，因为回合结束前，手动清零部分冲击，这些冲击不影响下一回合运行
B13: 说明 | C13: 深色表示相关状态的，浅色表示被影响的，更深色表示已经处理完毕的。 | E13: 字体颜色 | F13: 在银行只变量集之内的，手动设定的数字
E14: 字体颜色 | F14: 在银行之变量集之内的，由Excel公式计算设定的数字
E15: 字体颜色 | F15: 在银行之变量集之外的，由Excel公式计算设定的数字
E16: 字体颜色 | F16: 有疑问的，需要解决的
E19: 说明 | F19: 深色表示相关状态的，浅色表示被影响的，更深色表示已经处理完毕的。

Sheet 参数
A1: 贷款损失率； | B1: 可担保资产用于获取回购资金时的折价率； | C1: 召回流动资产以获取流动性，召回比例 | D1: 外生给定现金储备率； | E1: 所有者权益占比； | F1: 可担保资产占比； | G1: 各银行之同业资产之和比上各银行之总资产之和；
A2: LGD | B2: HR | C2: WR | D2: CRR | E2: ER | F2: CAR | G2: TIBAR
A3: 0.4 | B3: 0.1 | C3: 0.2 | D3: 0.02 | E3: 0.05 | F3: 0.1 | G3: 0.3

Sheet BB之过程-theta_Shock_exBI_t=1
A1: 子过程 | B1: tau | C1: t | D1: id | E1: name | F1: A_R | G1: A_Q | H1: A_P | I1: A_other | J1: A_exBI | K1: A_BI_all | L1: A_all | M1: Z_D | N1: Z_other | O1: Z_exBI | P1: Z_BI_all | Q1: Z_all | R1: E_all | S1: Bo_D | T1: Li_P | U1: Lo_BI_all | V1: Li_BI_all | W1: Bi_BI_all | X1: Bo_BI_all | Y1: Shock_B_A | Z1: Shock_B_Z | AA1: Shock_B_def_t | AB1: Shock_B_run_t | AC1: BB.Shock_P_def_t | AD1: BB.Shock_D_def_s | AE1: BB.Shock_D_run_t | AF1: BB.Shock_P_run_s | AG1: BB.Shock_BI_def_s | AH1: BB.Shock_BI_def_t | AI1: BB.Shock_BI_run_ilq_s | AJ1: BB.Shock_BI_run_ilq_t | AK1: BB.Shock_BI_run_br_s | AL1: BB.Shock_BI_run_br_t | AM1: BB.Shock_BI_run_s | AN1: BB.Shock_BI_run_t | AO1: BB.Shock_BI_s | AP1: BB.Shock_BI_t | AR1: name | AS1: A_R | AT1: A_Q | AU1: A_P | AV1: A_other | AW1: A_exBI | AX1: A_BI_all | AY1: A_all | AZ1: Z_D | BA1: Z_other | BB1: Z_exBI | BC1: Z_BI_all | BD1: Z_all | BE1: E_all | BF1: Shock_B_A | BG1: Shock_B_Z | BH1: BB.Shock_L_exBI_s | BI1: BB.Shock_D_s | BJ1: BB.Shock_BI_def_s | BK1: BB.Shock_BI_run_ilq_s | BL1: BB.Shock_BI_run_br_s | BM1: BB.Shock_BI_def_t | BN1: BB.Shock_BI_run_ilq_t | BO1: BB.Shock_BI_run_br_t | BP1: BB.Shock_BI_run_s | BQ1: BB.Shock_BI_run_t | BR1: BB.Shock_BI_s | BS1: BB.Shock_BI_t
A2: 1 | B2: 1 | C2: 0 | D2: 1 | E2: BK1 | F2: 0 | G2: 477.125 | H2: 1631.73 | I2: 0 | J2: =F2+G2+H2+I2 -> 2108.855 | K2: 2185.24 | L2: =J2+K2 -> 4294.095 | M2: 3160.99 | N2: 0 | O2: =M2+N2 -> 3160.99 | P2: 959.6 | Q2: =P2+O2 -> 4120.59 | R2: =MAX(L2-Q2,0) -> 173.505 | S2: 0 | T2: 0 | U2: 0 | V2: 0 | W2: 0 | X2: 0 | Y2: 0 | Z2: 0 | AA2: =AC2+AH2 -> 1631.73 | AB2: =AE2+AN2 -> 0 | AC2: 1631.73 | AD2: 0 | AE2: 0 | AF2: 0 | AG2: 0 | AH2: 0 | AI2: 0 | AJ2: 0 | AK2: 0 | AL2: 0 | AM2: =AI2+AK2 -> 0 | AN2: =AJ2+AL2 -> 0 | AO2: =AG2+AM2 -> 0 | AP2: =AH2+AN2 -> 0
D3: 2 | E3: BK2 | F3: 0 | G3: 587.693 | H3: 4303.24 | I3: 0 | J3: =F3+G3+H3+I3 -> 4890.933 | K3: 398.37 | L3: =J3+K3 -> 5289.303 | M3: 3231.37 | N3: 0 | O3: =M3+N3 -> 3231.37 | P3: 1844.24 | Q3: =P3+O3 -> 5075.61 | R3: =MAX(L3-Q3,0) -> 213.693 | S3: 0 | T3: 0 | U3: 0 | V3: 0 | W3: 0 | X3: 0 | Y3: 0 | Z3: 0 | AA3: =AC3+AH3 -> 0 | AB3: =AE3+AN3 -> 0 | AC3: 0 | AD3: 0 | AE3: 0 | AF3: 0 | AG3: 0 | AH3: 0 | AI3: 0 | AJ3: 0 | AK3: 0 | AL3: 0 | AM3: =AI3+AK3 -> 0 | AN3: =AJ3+AL3 -> 0 | AO3: =AG3+AM3 -> 0 | AP3: =AH3+AN3 -> 0
D4: 3 | E4: BK3 | F4: 0 | G4: 513.847 | H4: 3379.72 | I4: 0 | J4: =F4+G4+H4+I4 -> 3893.567 | K4: 730.99 | L4: =J4+K4 -> 4624.557 | M4: 3184.36 | N4: 0 | O4: =M4+N4 -> 3184.36 | P4: 1253.34 | Q4: =P4+O4 -> 4437.7 | R4: =MAX(L4-Q4,0) -> 186.857 | S4: 0 | T4: 0 | U4: 0 | V4: 0 | W4: 0 | X4: 0 | Y4: 0 | Z4: 0 | AA4: =AC4+AH4 -> 0 | AB4: =AE4+AN4 -> 0 | AC4: 0 | AD4: 0 | AE4: 0 | AF4: 0 | AG4: 0 | AH4: 0 | AI4: 0 | AJ4: 0 | AK4: 0 | AL4: 0 | AM4: =AI4+AK4 -> 0 | AN4: =AJ4+AL4 -> 0 | AO4: =AG4+AM4 -> 0 | AP4: =AH4+AN4 -> 0
D5: 4 | E5: BK4 | F5: 0 | G5: 713.662 | H5: 4351.47 | I5: 0 | J5: =F5+G5+H5+I5 -> 5065.132 | K5: 1357.75 | L5: =J5+K5 -> 6422.882 | M5: 3311.51 | N5: 0 | O5: =M5+N5 -> 3311.51 | P5: 2851.85 | Q5: =P5+O5 -> 6163.36 | R5: =MAX(L5-Q5,0) -> 259.522 | S5: 0 | T5: 0 | U5: 0 | V5: 0 | W5: 0 | X5: 0 | Y5: 0 | Z5: 0 | AA5: =AC5+AH5 -> 0 | AB5: =AE5+AN5 -> 0 | AC5: 0 | AD5: 0 | AE5: 0 | AF5: 0 | AG5: 0 | AH5: 0 | AI5: 0 | AJ5: 0 | AK5: 0 | AL5: 0 | AM5: =AI5+AK5 -> 0 | AN5: =AJ5+AL5 -> 0 | AO5: =AG5+AM5 -> 0 | AP5: =AH5+AN5 -> 0
D6: 5 | E6: BK5 | F6: 0 | G6: 417.257 | H6: 620.69 | I6: 0 | J6: =F6+G6+H6+I6 -> 1037.947 | K6: 2717.39 | L6: =J6+K6 -> 3755.337 | M6: 3122.9 | N6: 0 | O6: =M6+N6 -> 3122.9 | P6: 480.71 | Q6: =P6+O6 -> 3603.61 | R6: =MAX(L6-Q6,0) -> 151.727 | S6: 0 | T6: 0 | U6: 0 | V6: 0 | W6: 0 | X6: 0 | Y6: 0 | Z6: 0 | AA6: =AC6+AH6 -> 0 | AB6: =AE6+AN6 -> 0 | AC6: 0 | AD6: 0 | AE6: 0 | AF6: 0 | AG6: 0 | AH6: 0 | AI6: 0 | AJ6: 0 | AK6: 0 | AL6: 0 | AM6: =AI6+AK6 -> 0 | AN6: =AJ6+AL6 -> 0 | AO6: =AG6+AM6 -> 0 | AP6: =AH6+AN6 -> 0
F7: =SUM(F2:F6) -> 0 | G7: =SUM(G2:G6) -> 2709.584 | H7: =SUM(H2:H6) -> 14286.85 | I7: =SUM(I2:I6) -> 0 | J7: =SUM(J2:J6) -> 16996.434 | K7: =SUM(K2:K6) -> 7389.74 | L7: =SUM(L2:L6) -> 24386.174 | M7: =SUM(M2:M6) -> 16011.13 | ... AP7: =SUM(AP2:AP6) -> 0
B9: 1 | C9: 1 | D9: 1 | E9: BK1 | F9: 0 | G9: 477.125 | H9: 1631.73 | I9: 0 | J9: =F9+G9+H9+I9 -> 2108.855 | K9: 2185.24 | L9: =J9+K9 -> 4294.095 | M9: 3160.99 | N9: 0 | O9: =M9+N9 -> 3160.99 | P9: 959.6 | Q9: =P9+O9 -> 4120.59 | R9: =MAX(L9-Q9,0) -> 173.505 | S9: 0 | T9: 0 | U9: 0 | V9: 0 | W9: 0 | X9: 0 | Y9: 1631.73 | Z9: 0 | AA9: =AC9+AH9 -> 1631.73 | AB9: =AE9+AN9 -> 0 | AC9: 1631.73 | AD9: 0 | AE9: 0 | AF9: 0 | AG9: 0 | AH9: 0 | AI9: 0 | AJ9: 0 | AK9: 0 | AL9: 0 | AM9: =AI9+AK9 -> 0 | AN9: =AJ9+AL9 -> 0 | AO9: =AG9+AM9 -> 0 | AP9: =AH9+AN9 -> 0
D10: 2 | E10: BK2 | F10: 0 | G10: 587.693 | H10: 4303.24 | I10: 0 | J10: =F10+G10+H10+I10 -> 4890.933 | K10: 398.37 | L10: =J10+K10 -> 5289.303 | M10: 3231.37 | N10: 0 | O10: =M10+N10 -> 3231.37 | P10: 1844.24 | Q10: =P10+O10 -> 5075.61 | R10: =MAX(L10-Q10,0) -> 213.693 | S10: 0 | T10: 0 | U10: 0 | V10: 0 | W10: 0 | X10: 0 | Y10: 0 | Z10: 0 | AA10: =AC10+AH10 -> 0 | AB10: =AE10+AN10 -> 0 | AC10: 0 | AD10: 0 | AE10: 0 | AF10: 0 | AG10: 0 | AH10: 0 | AI10: 0 | AJ10: 0 | AK10: 0 | AL10: 0 | AM10: =AI10+AK10 -> 0 | AN10: =AJ10+AL10 -> 0 | AO10: =AG10+AM10 -> 0 | AP10: =AH10+AN10 -> 0
D11: 3 | E11: BK3 | F11: 0 | G11: 513.847 | H11: 3379.72 | I11: 0 | J11: =F11+G11+H11+I11 -> 3893.567 | K11: 730.99 | L11: =J11+K11 -> 4624.557 | M11: 3184.36 | N11: 0 | O11: =M11+N11 -> 3184.36 | P11: 1253.34 | Q11: =P11+O11 -> 4437.7 | R11: =MAX(L11-Q11,0) -> 186.857 | S11: 0 | T11: 0 | U11: 0 | V11: 0 | W11: 0 | X11: 0 | Y11: 0 | Z11: 0 | AA11: =AC11+AH11 -> 0 | AB11: =AE11+AN11 -> 0 | AC11: 0 | AD11: 0 | AE11: 0 | AF11: 0 | AG11: 0 | AH11: 0 | AI11: 0 | AJ11: 0 | AK11: 0 | AL11: 0 | AM11: =AI11+AK11 -> 0 | AN11: =AJ11+AL11 -> 0 | AO11: =AG11+AM11 -> 0 | AP11: =AH11+AN11 -> 0
D12: 4 | E12: BK4 | F12: 0 | G12: 713.662 | H12: 4351.47 | I12: 0 | J12: =F12+G12+H12+I12 -> 5065.132 | K12: 1357.75 | L12: =J12+K12 -> 6422.882 | M12: 3311.51 | N12: 0 | O12: =M12+N12 -> 3311.51 | P12: 2851.85 | Q12: =P12+O12 -> 6163.36 | R12: =MAX(L12-Q12,0) -> 259.522 | S12: 0 | T12: 0 | U12: 0 | V12: 0 | W12: 0 | X12: 0 | Y12: 0 | Z12: 0 | AA12: =AC12+AH12 -> 0 | AB12: =AE12+AN12 -> 0 | AC12: 0 | AD12: 0 | AE12: 0 | AF12: 0 | AG12: 0 | AH12: 0 | AI12: 0 | AJ12: 0 | AK12: 0 | AL12: 0 | AM12: =AI12+AK12 -> 0 | AN12: =AJ12+AL12 -> 0 | AO12: =AG12+AM12 -> 0 | AP12: =AH12+AN12 -> 0
D13: 5 | E13: BK5 | F13: 0 | G13: 417.257 | H13: 620.69 | I13: 0 | J13: =F13+G13+H13+I13 -> 1037.947 | K13: 2717.39 | L13: =J13+K13 -> 3755.337 | M13: 3122.9 | N13: 0 | O13: =M13+N13 -> 3122.9 | P13: 480.71 | Q13: =P13+O13 -> 3603.61 | R13: =MAX(L13-Q13,0) -> 151.727 | S13: 0 | T13: 0 | U13: 0 | V13: 0 | W13: 0 | X13: 0 | Y13: 0 | Z13: 0 | AA13: =AC13+AH13 -> 0 | AB13: =AE13+AN13 -> 0 | AC13: 0 | AD13: 0 | AE13: 0 | AF13: 0 | AG13: 0 | AH13: 0 | AI13: 0 | AJ13: 0 | AK13: 0 | AL13: 0 | AM13: =AI13+AK13 -> 0 | AN13: =AJ13+AL13 -> 0 | AO13: =AG13+AM13 -> 0 | AP13: =AH13+AN13 -> 0
F14: =SUM(F9:F13) -> 0 | G14: =SUM(G9:G13) -> 2709.584 | H14: =SUM(H9:H13) -> 14286.85 | I14: =SUM(I9:I13) -> 0 | J14: =SUM(J9:J13) -> 16996.434 | K14: =SUM(K9:K13) -> 7389.74 | L14: =SUM(L9:L13) -> 24386.174 | M14: =SUM(M9:M13) -> 16011.13 | ... AP14: =SUM(AP9:AP13) -> 0
B16: 1 | C16: 2 | D16: 1 | E16: BK1 | F16: 0 | G16: 477.125 | H16: 0 | I16: 0 | J16: =F16+G16+H16+I16 -> 477.125 | K16: 2185.24 | L16: =J16+K16 -> 2662.365 | M16: 2042.355 | N16: 0 | O16: =M16+N16 -> 2042.355 | P16: 620.009 | Q16: =P16+O16 -> 2662.364 | R16: 0 | S16: 0 | T16: 0 | U16: 0 | V16: 0 | W16: 0 | X16: 0 | Y16: 1631.73 | Z16: 0 | AA16: =AC16+AH16 -> 0 | AB16: =AE16+AN16 -> 0 | AC16: 0 | AD16: 1118.6423 | AE16: 0 | AF16: 0 | AG16: 339.6 | AH16: 0 | AI16: 0 | AJ16: 0 | AK16: 0 | AL16: 0 | AM16: =AI16+AK16 -> 0 | AN16: =AJ16+AL16 -> 0 | AO16: =AG16+AM16 -> 339.6 | AP16: =AH16+AN16 -> 0
D17: 2 | E17: BK2 | F17: 0 | G17: 587.693 | H17: 4303.24 | I17: 0 | J17: =F17+G17+H17+I17 -> 4890.933 | K17: 398.37 | L17: =J17+K17 -> 5289.303 | M17: 3231.37 | N17: 0 | O17: =M17+N17 -> 3231.37 | P17: 1844.24 | Q17: =P17+O17 -> 5075.61 | R17: 213.693 | S17: 0 | T17: 0 | U17: 0 | V17: 0 | W17: 0 | X17: 0 | Y17: 0 | Z17: 0 | AA17: =AC17+AH17 -> 0 | AB17: =AE17+AN17 -> 0 | AC17: 0 | AD17: 0 | AE17: 0 | AF17: 0 | AG17: 0 | AH17: 0 | AI17: 0 | AJ17: 0 | AK17: 0 | AL17: 0 | AM17: =AI17+AK17 -> 0 | AN17: =AJ17+AL17 -> 0 | AO17: =AG17+AM17 -> 0 | AP17: =AH17+AN17 -> 0
D18: 3 | E18: BK3 | F18: 0 | G18: 513.847 | H18: 3379.72 | I18: 0 | J18: =F18+G18+H18+I18 -> 3893.567 | K18: 730.99 | L18: =J18+K18 -> 4624.557 | M18: 3184.36 | N18: 0 | O18: =M18+N18 -> 3184.36 | P18: 1253.34 | Q18: =P18+O18 -> 4437.7 | R18: 186.857 | S18: 0 | T18: 0 | U18: 0 | V18: 0 | W18: 0 | X18: 0 | Y18: 0 | Z18: 0 | AA18: =AC18+AH18 -> 0 | AB18: =AE18+AN18 -> 0 | AC18: 0 | AD18: 0 | AE18: 0 | AF18: 0 | AG18: 0 | AH18: 0 | AI18: 0 | AJ18: 0 | AK18: 0 | AL18: 0 | AM18: =AI18+AK18 -> 0 | AN18: =AJ18+AL18 -> 0 | AO18: =AG18+AM18 -> 0 | AP18: =AH18+AN18 -> 0
D19: 4 | E19: BK4 | F19: 0 | G19: 713.662 | H19: 4351.47 | I19: 0 | J19: =F19+G19+H19+I19 -> 5065.132 | K19: 1357.75 | L19: =J19+K19 -> 6422.882 | M19: 3311.51 | N19: 0 | O19: =M19+N19 -> 3311.51 | P19: 2851.85 | Q19: =P19+O19 -> 6163.36 | R19: 259.522 | S19: 0 | T19: 0 | U19: 0 | V19: 0 | W19: 0 | X19: 0 | Y19: 0 | Z19: 0 | AA19: =AC19+AH19 -> 0 | AB19: =AE19+AN19 -> 0 | AC19: 0 | AD19: 0 | AE19: 0 | AF19: 0 | AG19: 0 | AH19: 0 | AI19: 0 | AJ19: 0 | AK19: 0 | AL19: 0 | AM19: =AI19+AK19 -> 0 | AN19: =AJ19+AL19 -> 0 | AO19: =AG19+AM19 -> 0 | AP19: =AH19+AN19 -> 0
D20: 5 | E20: BK5 | F20: 0 | G20: 417.257 | H20: 620.69 | I20: 0 | J20: =F20+G20+H20+I20 -> 1037.947 | K20: 2717.39 | L20: =J20+K20 -> 3755.337 | M20: 3122.9 | N20: 0 | O20: =M20+N20 -> 3122.9 | P20: 480.71 | Q20: =P20+O20 -> 3603.61 | R20: 151.727 | S20: 0 | T20: 0 | U20: 0 | V20: 0 | W20: 0 | X20: 0 | Y20: 0 | Z20: 0 | AA20: =AC20+AH20 -> 0 | AB20: =AE20+AN20 -> 0 | AC20: 0 | AD20: 0 | AE20: 0 | AF20: 0 | AG20: 0 | AH20: 0 | AI20: 0 | AJ20: 0 | AK20: 0 | AL20: 0 | AM20: =AI20+AK20 -> 0 | AN20: =AJ20+AL20 -> 0 | AO20: =AG20+AM20 -> 0 | AP20: =AH20+AN20 -> 0
F21: =SUM(F16:F20) -> 0 | G21: =SUM(G16:G20) -> 2709.584 | H21: =SUM(H16:H20) -> 12655.12 | I21: =SUM(I16:I20) -> 0 | J21: =SUM(J16:J20) -> 15364.704 | K21: =SUM(K16:K20) -> 7389.74 | L21: =SUM(L16:L20) -> 22754.444 | M21: =SUM(M16:M20) -> 14892.495 | ... AP21: =SUM(AP16:AP20) -> 0
B23: 2 | C23: 1 | D23: 1 | E23: BK1 | F23: 0 | G23: 477.125 | H23: 0 | I23: 0 | J23: =F23+G23+H23+I23 -> 477.125 | K23: 2185.24 | L23: =J23+K23 -> 2662.365 | M23: 2042.355 | N23: 0 | O23: =M23+N23 -> 2042.355 | P23: 620.009 | Q23: =P23+O23 -> 2662.364 | R23: 0 | S23: 0 | T23: 0 | U23: 0 | V23: 0 | W23: 0 | X23: 0 | Y23: 0 | Z23: 0 | AA23: =AC23+AH23 -> 0 | AB23: =AE23+AN23 -> 0 | AC23: 0 | AD23: 1118.6423 | AE23: 0 | AF23: 0 | AG23: 339.6 | AH23: 0 | AI23: 0 | AJ23: 0 | AK23: 0 | AL23: 0 | AM23: =AI23+AK23 -> 0 | AN23: =AJ23+AL23 -> 0 | AO23: =AG23+AM23 -> 339.6 | AP23: =AH23+AN23 -> 0
D24: 2 | E24: BK2 | F24: 0 | G24: 587.693 | H24: 4303.24 | I24: 0 | J24: =F24+G24+H24+I24 -> 4890.933 | K24: 398.37 | L24: =J24+K24 -> 5289.303 | M24: 3231.37 | N24: 0 | O24: =M24+N24 -> 3231.37 | P24: 1844.24 | Q24: =P24+O24 -> 5075.61 | R24: 213.693 | S24: 0 | T24: 0 | U24: 0 | V24: 0 | W24: 0 | X24: 0 | Y24: 38.698 | Z24: 0 | AA24: =AC24+AH24 -> 38.698 | AB24: =AE24+AN24 -> 0 | AC24: 0 | AD24: 0 | AE24: 0 | AF24: 0 | AG24: 0 | AH24: 38.698 | AI24: 0 | AJ24: 0 | AK24: 0 | AL24: 0 | AM24: =AI24+AK24 -> 0 | AN24: =AJ24+AL24 -> 0 | AO24: =AG24+AM24 -> 0 | AP24: =AH24+AN24 -> 38.698
D25: 3 | E25: BK3 | F25: 0 | G25: 513.847 | H25: 3379.72 | I25: 0 | J25: =F25+G25+H25+I25 -> 3893.567 | K25: 730.99 | L25: =J25+K25 -> 4624.557 | M25: 3184.36 | N25: 0 | O25: =M25+N25 -> 3184.36 | P25: 1253.34 | Q25: =P25+O25 -> 4437.7 | R25: 186.857 | S25: 0 | T25: 0 | U25: 0 | V25: 0 | W25: 0 | X25: 0 | Y25: 258.688 | Z25: 0 | AA25: =AC25+AH25 -> 258.688 | AB25: =AE25+AN25 -> 0 | AC25: 0 | AD25: 0 | AE25: 0 | AF25: 0 | AG25: 0 | AH25: 258.688 | AI25: 0 | AJ25: 0 | AK25: 0 | AL25: 0 | AM25: =AI25+AK25 -> 0 | AN25: =AJ25+AL25 -> 0 | AO25: =AG25+AM25 -> 0 | AP25: =AH25+AN25 -> 258.688
D26: 4 | E26: BK4 | F26: 0 | G26: 713.662 | H26: 4351.47 | I26: 0 | J26: =F26+G26+H26+I26 -> 5065.132 | K26: 1357.75 | L26: =J26+K26 -> 6422.882 | M26: 3311.51 | N26: 0 | O26: =M26+N26 -> 3311.51 | P26: 2851.85 | Q26: =P26+O26 -> 6163.36 | R26: 259.522 | S26: 0 | T26: 0 | U26: 0 | V26: 0 | W26: 0 | X26: 0 | Y26: 42.205 | Z26: 0 | AA26: =AC26+AH26 -> 42.205 | AB26: =AE26+AN26 -> 0 | AC26: 0 | AD26: 0 | AE26: 0 | AF26: 0 | AG26: 0 | AH26: 42.205 | AI26: 0 | AJ26: 0 | AK26: 0 | AL26: 0 | AM26: =AI26+AK26 -> 0 | AN26: =AJ26+AL26 -> 0 | AO26: =AG26+AM26 -> 0 | AP26: =AH26+AN26 -> 42.205
D27: 5 | E27: BK5 | F27: 0 | G27: 417.257 | H27: 620.69 | I27: 0 | J27: =F27+G27+H27+I27 -> 1037.947 | K27: 2717.39 | L27: =J27+K27 -> 3755.337 | M27: 3122.9 | N27: 0 | O27: =M27+N27 -> 3122.9 | P27: 480.71 | Q27: =P27+O27 -> 3603.61 | R27: 151.727 | S27: 0 | T27: 0 | U27: 0 | V27: 0 | W27: 0 | X27: 0 | Y27: 0 | Z27: 0 | AA27: =AC27+AH27 -> 0 | AB27: =AE27+AN27 -> 0 | AC27: 0 | AD27: 0 | AE27: 0 | AF27: 0 | AG27: 0 | AH27: 0 | AI27: 0 | AJ27: 0 | AK27: 0 | AL27: 0 | AM27: =AI27+AK27 -> 0 | AN27: =AJ27+AL27 -> 0 | AO27: =AG27+AM27 -> 0 | AP27: =AH27+AN27 -> 0
F28: =SUM(F23:F27) -> 0 | G28: =SUM(G23:G27) -> 2709.584 | H28: =SUM(H23:H27) -> 12655.12 | I28: =SUM(I23:I27) -> 0 | J28: =SUM(J23:J27) -> 15364.704 | K28: =SUM(K23:K27) -> 7389.74 | L28: =SUM(L23:L27) -> 22754.444 | M28: =SUM(M23:M27) -> 14892.495 | ... AP28: =SUM(AP23:AP27) -> 339.591
B30: 2 | C30: 2 | D30: 1 | E30: BK1 | F30: 0 | G30: 477.125 | H30: 0 | I30: 0 | J30: =F30+G30+H30+I30 -> 477.125 | K30: 2185.24 | L30: =J30+K30 -> 2662.365 | M30: 2042.355 | N30: 0 | O30: =M30+N30 -> 2042.355 | P30: 620.009 | Q30: =P30+O30 -> 2662.364 | R30: 0 | S30: 0 | T30: 0 | U30: 0 | V30: 0 | W30: 0 | X30: 0 | Y30: 0 | Z30: 0 | AA30: =AC30+AH30 -> 0 | AB30: =AE30+AN30 -> 0 | AC30: 0 | AD30: 0 | AE30: 0 | AF30: 0 | AG30: 0 | AH30: 0 | AI30: 0 | AJ30: 0 | AK30: 0 | AL30: 0 | AM30: =AI30+AK30 -> 0 | AN30: =AJ30+AL30 -> 0 | AO30: =AG30+AM30 -> 0 | AP30: =AH30+AN30 -> 0
D31: 2 | E31: BK2 | F31: 0 | G31: 587.693 | H31: 4303.24 | I31: 0 | J31: =F31+G31+H31+I31 -> 4890.933 | K31: 359.67215 | L31: =J31+K31 -> 5250.6052 | M31: 3231.37 | N31: 0 | O31: =M31+N31 -> 3231.37 | P31: 1844.24 | Q31: =P31+O31 -> 5075.61 | R31: 174.98502 | S31: 0 | T31: 0 | U31: 0 | V31: 0 | W31: 0 | X31: 0 | Y31: 38.698 | Z31: 0 | AA31: =AC31+AH31 -> 38.698 | AB31: =AE31+AN31 -> 0 | AC31: 0 | AD31: 0 | AE31: 0 | AF31: 0 | AG31: 0 | AH31: 38.698 | AI31: 0 | AJ31: 0 | AK31: 0 | AL31: 0 | AM31: =AI31+AK31 -> 0 | AN31: =AJ31+AL31 -> 0 | AO31: =AG31+AM31 -> 0 | AP31: =AH31+AN31 -> 38.698
D32: 3 | E32: BK3 | F32: 0 | G32: 513.847 | H32: 3379.72 | I32: 0 | J32: =F32+G32+H32+I32 -> 3893.567 | K32: 472.30005 | L32: =J32+K32 -> 4365.867 | M32: 3132.8074 | N32: 0 | O32: =M32+N32 -> 3132.8074 | P32: 1233.0492 | Q32: =P32+O32 -> 4365.8566 | R32: 0 | S32: 0 | T32: 0 | U32: 0 | V32: 0 | W32: 0 | X32: 0 | Y32: 258.688 | Z32: 0 | AA32: =AC32+AH32 -> 258.688 | AB32: =AE32+AN32 -> 0 | AC32: 0 | AD32: 51.552734 | AE32: 0 | AF32: 0 | AG32: 20.290771 | AH32: 258.688 | AI32: 0 | AJ32: 0 | AK32: 0 | AL32: 0 | AM32: =AI32+AK32 -> 0 | AN32: =AJ32+AL32 -> 0 | AO32: =AG32+AM32 -> 20.290771 | AP32: =AH32+AN32 -> 258.688
D33: 4 | E33: BK4 | F33: 0 | G33: 713.662 | H33: 4351.47 | I33: 0 | J33: =F33+G33+H33+I33 -> 5065.132 | K33: 1315.545 | L33: =J33+K33 -> 6380.677 | M33: 3311.51 | N33: 0 | O33: =M33+N33 -> 3311.51 | P33: 2851.85 | Q33: =P33+O33 -> 6163.36 | R33: 217.30754 | S33: 0 | T33: 0 | U33: 0 | V33: 0 | W33: 0 | X33: 0 | Y33: 42.205 | Z33: 0 | AA33: =AC33+AH33 -> 42.205 | AB33: =AE33+AN33 -> 0 | AC33: 0 | AD33: 0 | AE33: 0 | AF33: 0 | AG33: 0 | AH33: 42.205 | AI33: 0 | AJ33: 0 | AK33: 0 | AL33: 0 | AM33: =AI33+AK33 -> 0 | AN33: =AJ33+AL33 -> 0 | AO33: =AG33+AM33 -> 0 | AP33: =AH33+AN33 -> 42.205
D34: 5 | E34: BK5 | F34: 0 | G34: 417.257 | H34: 620.69 | I34: 0 | J34: =F34+G34+H34+I34 -> 1037.947 | K34: 2717.39 | L34: =J34+K34 -> 3755.337 | M34: 3122.9 | N34: 0 | O34: =M34+N34 -> 3122.9 | P34: 480.71 | Q34: =P34+O34 -> 3603.61 | R34: 151.727 | S34: 0 | T34: 0 | U34: 0 | V34: 0 | W34: 0 | X34: 0 | Y34: 0 | Z34: 0 | AA34: =AC34+AH34 -> 0 | AB34: =AE34+AN34 -> 0 | AC34: 0 | AD34: 0 | AE34: 0 | AF34: 0 | AG34: 0 | AH34: 0 | AI34: 0 | AJ34: 0 | AK34: 0 | AL34: 0 | AM34: =AI34+AK34 -> 0 | AN34: =AJ34+AL34 -> 0 | AO34: =AG34+AM34 -> 0 | AP34: =AH34+AN34 -> 0
F35: =SUM(F30:F34) -> 0 | G35: =SUM(G30:G34) -> 2709.584 | H35: =SUM(H30:H34) -> 12655.12 | I35: =SUM(I30:I34) -> 0 | J35: =SUM(J30:J34) -> 15364.704 | K35: =SUM(K30:K34) -> 7050.1472 | L35: =SUM(L30:L34) -> 22414.851 | M35: =SUM(M30:M34) -> 14840.942 | ... AP35: =SUM(AP30:AP34) -> 339.591
B37: 3 | C37: 1 | D37: 1 | E37: BK1 | F37: 0 | G37: 477.125 | H37: 0 | I37: 0 | J37: =F37+G37+H37+I37 -> 477.125 | K37: 2185.24 | L37: =J37+K37 -> 2662.365 | M37: 2042.355 | N37: 0 | O37: =M37+N37 -> 2042.355 | P37: 620.009 | Q37: =P37+O37 -> 2662.364 | R37: 0 | S37: 0 | T37: 0 | U37: 0 | V37: 0 | W37: 0 | X37: 0 | Y37: 0 | Z37: 0 | AA37: =AC37+AH37 -> 0 | AB37: =AE37+AN37 -> 0 | AC37: 0 | AD37: 0 | AE37: 0 | AF37: 0 | AG37: 0 | AH37: 0 | AI37: 0 | AJ37: 0 | AK37: 0 | AL37: 0 | AM37: =AI37+AK37 -> 0 | AN37: =AJ37+AL37 -> 0 | AO37: =AG37+AM37 -> 0 | AP37: =AH37+AN37 -> 0
D38: 2 | E38: BK2 | F38: 0 | G38: 587.693 | H38: 4303.24 | I38: 0 | J38: =F38+G38+H38+I38 -> 4890.933 | K38: 359.67215 | L38: =J38+K38 -> 5250.6052 | M38: 3231.37 | N38: 0 | O38: =M38+N38 -> 3231.37 | P38: 1844.24 | Q38: =P38+O38 -> 5075.61 | R38: 174.98502 | S38: 0 | T38: 0 | U38: 0 | V38: 0 | W38: 0 | X38: 0 | Y38: 4.67905 | Z38: 0 | AA38: =AC38+AH38 -> 4.67905 | AB38: =AE38+AN38 -> 0 | AC38: 0 | AD38: 0 | AE38: 0 | AF38: 0 | AG38: 0 | AH38: 4.67905 | AI38: 0 | AJ38: 0 | AK38: 0 | AL38: 0 | AM38: =AI38+AK38 -> 0 | AN38: =AJ38+AL38 -> 0 | AO38: =AG38+AM38 -> 0 | AP38: =AH38+AN38 -> 4.67905
D39: 3 | E39: BK3 | F39: 0 | G39: 513.847 | H39: 3379.72 | I39: 0 | J39: =F39+G39+H39+I39 -> 3893.567 | K39: 472.30005 | L39: =J39+K39 -> 4365.867 | M39: 3132.8074 | N39: 0 | O39: =M39+N39 -> 3132.8074 | P39: 1233.0492 | Q39: =P39+O39 -> 4365.8566 | R39: 0 | S39: 0 | T39: 0 | U39: 0 | V39: 0 | W39: 0 | X39: 0 | Y39: 0 | Z39: 0 | AA39: =AC39+AH39 -> 0 | AB39: =AE39+AN39 -> 0 | AC39: 0 | AD39: 51.552734 | AE39: 0 | AF39: 0 | AG39: 20.290771 | AH39: 0 | AI39: 0 | AJ39: 0 | AK39: 0 | AL39: 0 | AM39: =AI39+AK39 -> 0 | AN39: =AJ39+AL39 -> 0 | AO39: =AG39+AM39 -> 20.290771 | AP39: =AH39+AN39 -> 0
D40: 4 | E40: BK4 | F40: 0 | G40: 713.662 | H40: 4351.47 | I40: 0 | J40: =F40+G40+H40+I40 -> 5065.132 | K40: 1315.545 | L40: =J40+K40 -> 6380.677 | M40: 3311.51 | N40: 0 | O40: =M40+N40 -> 3311.51 | P40: 2851.85 | Q40: =P40+O40 -> 6163.36 | R40: 217.30754 | S40: 0 | T40: 0 | U40: 0 | V40: 0 | W40: 0 | X40: 0 | Y40: 15.6117 | Z40: 0 | AA40: =AC40+AH40 -> 15.6117 | AB40: =AE40+AN40 -> 0 | AC40: 0 | AD40: 0 | AE40: 0 | AF40: 0 | AG40: 0 | AH40: 15.6117 | AI40: 0 | AJ40: 0 | AK40: 0 | AL40: 0 | AM40: =AI40+AK40 -> 0 | AN40: =AJ40+AL40 -> 0 | AO40: =AG40+AM40 -> 0 | AP40: =AH40+AN40 -> 15.6117
D41: 5 | E41: BK5 | F41: 0 | G41: 417.257 | H41: 620.69 | I41: 0 | J41: =F41+G41+H41+I41 -> 1037.947 | K41: 2717.39 | L41: =J41+K41 -> 3755.337 | M41: 3122.9 | N41: 0 | O41: =M41+N41 -> 3122.9 | P41: 480.71 | Q41: =P41+O41 -> 3603.61 | R41: 151.727 | S41: 0 | T41: 0 | U41: 0 | V41: 0 | W41: 0 | X41: 0 | Y41: 0 | Z41: 0 | AA41: =AC41+AH41 -> 0 | AB41: =AE41+AN41 -> 0 | AC41: 0 | AD41: 0 | AE41: 0 | AF41: 0 | AG41: 0 | AH41: 0 | AI41: 0 | AJ41: 0 | AK41: 0 | AL41: 0 | AM41: =AI41+AK41 -> 0 | AN41: =AJ41+AL41 -> 0 | AO41: =AG41+AM41 -> 0 | AP41: =AH41+AN41 -> 0
F42: =SUM(F37:F41) -> 0 | G42: =SUM(G37:G41) -> 2709.584 | H42: =SUM(H37:H41) -> 12655.12 | I42: =SUM(I37:I41) -> 0 | J42: =SUM(J37:J41) -> 15364.704 | K42: =SUM(K37:K41) -> 7050.1472 | L42: =SUM(L37:L41) -> 22414.851 | M42: =SUM(M37:M41) -> 14840.942 | ... AP42: =SUM(AP37:AP41) -> 20.29075
B44: 3 | C44: 2 | D44: 1 | E44: BK1 | F44: 0 | G44: 477.125 | H44: 0 | I44: 0 | J44: =F44+G44+H44+I44 -> 477.125 | K44: 2185.24 | L44: =J44+K44 -> 2662.365 | M44: 2042.355 | N44: 0 | O44: =M44+N44 -> 2042.355 | P44: 620.009 | Q44: =P44+O44 -> 2662.364 | R44: 0 | S44: 0 | T44: 0 | U44: 0 | V44: 0 | W44: 0 | X44: 0 | Y44: 0 | Z44: 0 | AA44: =AC44+AH44 -> 0 | AB44: =AE44+AN44 -> 0 | AC44: 0 | AD44: 0 | AE44: 0 | AF44: 0 | AG44: 0 | AH44: 0 | AI44: 0 | AJ44: 0 | AK44: 0 | AL44: 0 | AM44: =AI44+AK44 -> 0 | AN44: =AJ44+AL44 -> 0 | AO44: =AG44+AM44 -> 0 | AP44: =AH44+AN44 -> 0
D45: 2 | E45: BK2 | F45: 0 | G45: 587.693 | H45: 4303.24 | I45: 0 | J45: =F45+G45+H45+I45 -> 4890.933 | K45: 354.9931 | L45: =J45+K45 -> 5245.9261 | M45: 3231.37 | N45: 0 | O45: =M45+N45 -> 3231.37 | P45: 1844.24 | Q45: =P45+O45 -> 5075.61 | R45: 170.30597 | S45: 0 | T45: 0 | U45: 0 | V45: 0 | W45: 0 | X45: 0 | Y45: 4.67905 | Z45: 0 | AA45: =AC45+AH45 -> 0 | AB45: =AE45+AN45 -> 0 | AC45: 0 | AD45: 0 | AE45: 0 | AF45: 0 | AG45: 0 | AH45: 0 | AI45: 0 | AJ45: 0 | AK45: 0 | AL45: 0 | AM45: =AI45+AK45 -> 0 | AN45: =AJ45+AL45 -> 0 | AO45: =AG45+AM45 -> 0 | AP45: =AH45+AN45 -> 0
D46: 3 | E46: BK3 | F46: 0 | G46: 513.847 | H46: 3379.72 | I46: 0 | J46: =F46+G46+H46+I46 -> 3893.567 | K46: 472.30005 | L46: =J46+K46 -> 4365.867 | M46: 3132.8074 | N46: 0 | O46: =M46+N46 -> 3132.8074 | P46: 1233.0492 | Q46: =P46+O46 -> 4365.8566 | R46: 0 | S46: 0 | T46: 0 | U46: 0 | V46: 0 | W46: 0 | X46: 0 | Y46: 0 | Z46: 0 | AA46: =AC46+AH46 -> 0 | AB46: =AE46+AN46 -> 0 | AC46: 0 | AD46: 0 | AE46: 0 | AF46: 0 | AG46: 0 | AH46: 0 | AI46: 0 | AJ46: 0 | AK46: 0 | AL46: 0 | AM46: =AI46+AK46 -> 0 | AN46: =AJ46+AL46 -> 0 | AO46: =AG46+AM46 -> 0 | AP46: =AH46+AN46 -> 0
...

Sheet BI之过程-theta_Shock_exBI_t=1
A1: 子过程 | B1: id | C1: tau | D1: t | F1: A_BI | M1: Z_BI | T1: Shock_BI_def | AA1: Shock_BI_run_ilq | AH1: Shock_BI_run_br | AO1: Shock_BI_run
A2: 1 | C2: 1 | D2: 0 | F2: 0 | G2: 1728.55 | H2: 0 | I2: 134.46 | J2: 322.23 | K2: =SUM(F2:J2) -> 2185.24 | M2: 0 | N2: 109.35 | O2: 730.99 | P2: 119.26 | Q2: 0 | R2: =SUM(M2:Q2) -> 959.6 | T2: 0 | U2: 0 | V2: 0 | W2: 0 | X2: 0 | Y2: =SUM(T2:X2) -> 0 | AA2: 0 | AB2: 0 | AC2: 0 | AD2: 0 | AE2: 0 | AF2: =SUM(AA2:AE2) -> 0 | AH2: 0 | AI2: 0 | AJ2: 0 | AK2: 0 | AL2: 0 | AM2: =SUM(AH2:AL2) -> 0 | AO2: =AH2+AA2 -> 0 | AP2: =AI2+AB2 -> 0 | AQ2: =AJ2+AC2 -> 0 | AR2: =AK2+AD2 -> 0 | AS2: =AL2+AE2 -> 0 | AT2: =SUM(AO2:AS2) -> 0
F3: 109.35 | G3: 0 | H3: 289.02 | I3: 0 | J3: 0 | K3: =SUM(F3:J3) -> 398.37 | M3: 1728.55 | N3: 0 | O3: 0 | P3: 115.69 | Q3: 0 | R3: =SUM(M3:Q3) -> 1844.24 | T3: 0 | U3: 0 | V3: 0 | W3: 0 | X3: 0 | Y3: =SUM(T3:X3) -> 0 | AA3: 0 | AB3: 0 | AC3: 0 | AD3: 0 | AE3: 0 | AF3: =SUM(AA3:AE3) -> 0 | AH3: 0 | AI3: 0 | AJ3: 0 | AK3: 0 | AL3: 0 | AM3: =SUM(AH3:AL3) -> 0 | AO3: =AH3+AA3 -> 0 | AP3: =AI3+AB3 -> 0 | AQ3: =AJ3+AC3 -> 0 | AR3: =AK3+AD3 -> 0 | AS3: =AL3+AE3 -> 0 | AT3: =SUM(AO3:AS3) -> 0
F4: 730.99 | G4: 0 | H4: 0 | I4: 0 | J4: 0 | K4: =SUM(F4:J4) -> 730.99 | M4: 0 | N4: 289.02 | O4: 0 | P4: 964.32 | Q4: 0 | R4: =SUM(M4:Q4) -> 1253.34 | T4: 0 | U4: 0 | V4: 0 | W4: 0 | X4: 0 | Y4: =SUM(T4:X4) -> 0 | AA4: 0 | AB4: 0 | AC4: 0 | AD4: 0 | AE4: 0 | AF4: =SUM(AA4:AE4) -> 0 | AH4: 0 | AI4: 0 | AJ4: 0 | AK4: 0 | AL4: 0 | AM4: =SUM(AH4:AL4) -> 0 | AO4: =AH4+AA4 -> 0 | AP4: =AI4+AB4 -> 0 | AQ4: =AJ4+AC4 -> 0 | AR4: =AK4+AD4 -> 0 | AS4: =AL4+AE4 -> 0 | AT4: =SUM(AO4:AS4) -> 0
F5: 119.26 | G5: 115.69 | H5: 964.32 | I5: 0 | J5: 158.48 | K5: =SUM(F5:J5) -> 1357.75 | M5: 134.46 | N5: 0 | O5: 0 | P5: 0 | Q5: 2717.39 | R5: =SUM(M5:Q5) -> 2851.85 | T5: 0 | U5: 0 | V5: 0 | W5: 0 | X5: 0 | Y5: =SUM(T5:X5) -> 0 | AA5: 0 | AB5: 0 | AC5: 0 | AD5: 0 | AE5: 0 | AF5: =SUM(AA5:AE5) -> 0 | AH5: 0 | AI5: 0 | AJ5: 0 | AK5: 0 | AL5: 0 | AM5: =SUM(AH5:AL5) -> 0 | AO5: =AH5+AA5 -> 0 | AP5: =AI5+AB5 -> 0 | AQ5: =AJ5+AC5 -> 0 | AR5: =AK5+AD5 -> 0 | AS5: =AL5+AE5 -> 0 | AT5: =SUM(AO5:AS5) -> 0
F6: 0 | G6: 0 | H6: 0 | I6: 2717.39 | J6: 0 | K6: =SUM(F6:J6) -> 2717.39 | M6: 322.23 | N6: 0 | O6: 0 | P6: 158.48 | Q6: 0 | R6: =SUM(M6:Q6) -> 480.71 | T6: 0 | U6: 0 | V6: 0 | W6: 0 | X6: 0 | Y6: =SUM(T6:X6) -> 0 | AA6: 0 | AB6: 0 | AC6: 0 | AD6: 0 | AE6: 0 | AF6: =SUM(AA6:AE6) -> 0 | AH6: 0 | AI6: 0 | AJ6: 0 | AK6: 0 | AL6: 0 | AM6: =SUM(AH6:AL6) -> 0 | AO6: =AH6+AA6 -> 0 | AP6: =AI6+AB6 -> 0 | AQ6: =AJ6+AC6 -> 0 | AR6: =AK6+AD6 -> 0 | AS6: =AL6+AE6 -> 0 | AT6: =SUM(AO6:AS6) -> 0
F7: =SUM(F2:F6) -> 959.6 | G7: =SUM(G2:G6) -> 1844.24 | H7: =SUM(H2:H6) -> 1253.34 | I7: =SUM(I2:I6) -> 2851.85 | J7: =SUM(J2:J6) -> 480.71 | K7: =SUM(K2:K6) -> 7389.74 | M7: =SUM(M2:M6) -> 2185.24 | N7: =SUM(N2:N6) -> 398.37 | O7: =SUM(O2:O6) -> 730.99 | P7: =SUM(P2:P6) -> 1357.75 | Q7: =SUM(Q2:Q6) -> 2717.39 | R7: =SUM(R2:R6) -> 7389.74 | T7: =SUM(T2:T6) -> 0 | U7: =SUM(U2:U6) -> 0 | V7: =SUM(V2:V6) -> 0 | W7: =SUM(W2:W6) -> 0 | X7: =SUM(X2:X6) -> 0 | Y7: =SUM(Y2:Y6) -> 0 | AA7: =SUM(AA2:AA6) -> 0 | AB7: =SUM(AB2:AB6) -> 0 | AC7: =SUM(AC2:AC6) -> 0 | AD7: =SUM(AD2:AD6) -> 0 | AE7: =SUM(AE2:AE6) -> 0 | AF7: =SUM(AF2:AF6) -> 0 | AH7: =SUM(AH2:AH6) -> 0 | AI7: =SUM(AI2:AI6) -> 0 | AJ7: =SUM(AJ2:AJ6) -> 0 | AK7: =SUM(AK2:AK6) -> 0 | AL7: =SUM(AL2:AL6) -> 0 | AM7: =SUM(AM2:AM6) -> 0 | AO7: =SUM(AO2:AO6) -> 0 | AP7: =SUM(AP2:AP6) -> 0 | AQ7: =SUM(AQ2:AQ6) -> 0 | AR7: =SUM(AR2:AR6) -> 0 | AS7: =SUM(AS2:AS6) -> 0 | AT7: =SUM(AT2:AT6) -> 0
C9: 2 | D9: 1-1 | F9: 0 | G9: 1728.55 | H9: 0 | I9: 134.46 | J9: 322.23 | K9: =SUM(F9:J9) -> 2185.24 | M9: 0 | N9: 70.652 | O9: 472.302 | P9: 77.055 | Q9: 0 | R9: =SUM(M9:Q9) -> 620.009 | T9: 0 | U9: 0 | V9: 0 | W9: 0 | X9: 0 | Y9: =SUM(T9:X9) -> 0 | AA9: 0 | AB9: 0 | AC9: 0 | AD9: 0 | AE9: 0 | AF9: =SUM(AA9:AE9) -> 0 | AH9: 0 | AI9: 0 | AJ9: 0 | AK9: 0 | AL9: 0 | AM9: =SUM(AH9:AL9) -> 0 | AO9: =AH9+AA9 -> 0 | AP9: =AI9+AB9 -> 0 | AQ9: =AJ9+AC9 -> 0 | AR9: =AK9+AD9 -> 0 | AS9: =AL9+AE9 -> 0 | AT9: =SUM(AO9:AS9) -> 0
F10: 70.652 | G10: 0 | H10: 289.02 | I10: 0 | J10: 0 | K10: =SUM(F10:J10) -> 359.672 | M10: 1728.55 | N10: 0 | O10: 0 | P10: 115.69 | Q10: 0 | R10: =SUM(M10:Q10) -> 1844.24 | T10: 38.698 | U10: 0 | V10: 0 | W10: 0 | X10: 0 | Y10: =SUM(T10:X10) -> 38.698 | AA10: 0 | AB10: 0 | AC10: 0 | AD10: 0 | AE10: 0 | AF10: =SUM(AA10:AE10) -> 0 | AH10: 0 | AI10: 0 | AJ10: 0 | AK10: 0 | AL10: 0 | AM10: =SUM(AH10:AL10) -> 0 | AO10: =AH10+AA10 -> 0 | AP10: =AI10+AB10 -> 0 | AQ10: =AJ10+AC10 -> 0 | AR10: =AK10+AD10 -> 0 | AS10: =AL10+AE10 -> 0 | AT10: =SUM(AO10:AS10) -> 0
F11: 472.302 | G11: 0 | H11: 0 | I11: 0 | J11: 0 | K11: =SUM(F11:J11) -> 472.302 | M11: 0 | N11: 289.02 | O11: 0 | P11: 964.32 | Q11: 0 | R11: =SUM(M11:Q11) -> 1253.34 | T11: 258.688 | U11: 0 | V11: 0 | W11: 0 | X11: 0 | Y11: =SUM(T11:X11) -> 258.688 | AA11: 0 | AB11: 0 | AC11: 0 | AD11: 0 | AE11: 0 | AF11: =SUM(AA11:AE11) -> 0 | AH11: 0 | AI11: 0 | AJ11: 0 | AK11: 0 | AL11: 0 | AM11: =SUM(AH11:AL11) -> 0 | AO11: =AH11+AA11 -> 0 | AP11: =AI11+AB11 -> 0 | AQ11: =AJ11+AC11 -> 0 | AR11: =AK11+AD11 -> 0 | AS11: =AL11+AE11 -> 0 | AT11: =SUM(AO11:AS11) -> 0
F12: 77.055 | G12: 115.69 | H12: 964.32 | I12: 0 | J12: 158.48 | K12: =SUM(F12:J12) -> 1315.545 | M12: 134.46 | N12: 0 | O12: 0 | P12: 0 | Q12: 2717.39 | R12: =SUM(M12:Q12) -> 2851.85 | T12: 42.205 | U12: 0 | V12: 0 | W12: 0 | X12: 0 | Y12: =SUM(T12:X12) -> 42.205 | AA12: 0 | AB12: 0 | AC12: 0 | AD12: 0 | AE12: 0 | AF12: =SUM(AA12:AE12) -> 0 | AH12: 0 | AI12: 0 | AJ12: 0 | AK12: 0 | AL12: 0 | AM12: =SUM(AH12:AL12) -> 0 | AO12: =AH12+AA12 -> 0 | AP12: =AI12+AB12 -> 0 | AQ12: =AJ12+AC12 -> 0 | AR12: =AK12+AD12 -> 0 | AS12: =AL12+AE12 -> 0 | AT12: =SUM(AO12:AS12) -> 0
F13: 0 | G13: 0 | H13: 0 | I13: 2717.39 | J13: 0 | K13: =SUM(F13:J13) -> 2717.39 | M13: 322.23 | N13: 0 | O13: 0 | P13: 158.48 | Q13: 0 | R13: =SUM(M13:Q13) -> 480.71 | T13: 0 | U13: 0 | V13: 0 | W13: 0 | X13: 0 | Y13: =SUM(T13:X13) -> 0 | AA13: 0 | AB13: 0 | AC13: 0 | AD13: 0 | AE13: 0 | AF13: =SUM(AA13:AE13) -> 0 | AH13: 0 | AI13: 0 | AJ13: 0 | AK13: 0 | AL13: 0 | AM13: =SUM(AH13:AL13) -> 0 | AO13: =AH13+AA13 -> 0 | AP13: =AI13+AB13 -> 0 | AQ13: =AJ13+AC13 -> 0 | AR13: =AK13+AD13 -> 0 | AS13: =AL13+AE13 -> 0 | AT13: =SUM(AO13:AS13) -> 0
F14: =SUM(F9:F13) -> 620.009 | G14: =SUM(G9:G13) -> 1844.24 | H14: =SUM(H9:H13) -> 1253.34 | I14: =SUM(I9:I13) -> 2851.85 | J14: =SUM(J9:J13) -> 480.71 | K14: =SUM(K9:K13) -> 7050.149 | M14: =SUM(M9:M13) -> 2185.24 | N14: =SUM(N9:N13) -> 359.672 | O14: =SUM(O9:O13) -> 472.302 | P14: =SUM(P9:P13) -> 1315.545 | Q14: =SUM(Q9:Q13) -> 2717.39 | R14: =SUM(R9:R13) -> 7050.149 | T14: =SUM(T9:T13) -> 339.591 | U14: =SUM(U9:U13) -> 0 | V14: =SUM(V9:V13) -> 0 | W14: =SUM(W9:W13) -> 0 | X14: =SUM(X9:X13) -> 0 | Y14: =SUM(Y9:Y13) -> 339.591 | AA14: =SUM(AA9:AA13) -> 0 | AB14: =SUM(AB9:AB13) -> 0 | AC14: =SUM(AC9:AC13) -> 0 | AD14: =SUM(AD9:AD13) -> 0 | AE14: =SUM(AE9:AE13) -> 0 | AF14: =SUM(AF9:AF13) -> 0 | AH14: =SUM(AH9:AH13) -> 0 | AI14: =SUM(AI9:AI13) -> 0 | AJ14: =SUM(AJ9:AJ13) -> 0 | AK14: =SUM(AK9:AK13) -> 0 | AL14: =SUM(AL9:AL13) -> 0 | AM14: =SUM(AM9:AM13) -> 0 | AO14: =SUM(AO9:AO13) -> 0 | AP14: =SUM(AP9:AP13) -> 0 | AQ14: =SUM(AQ9:AQ13) -> 0 | AR14: =SUM(AR9:AR13) -> 0 | AS14: =SUM(AS9:AS13) -> 0 | AT14: =SUM(AT9:AT13) -> 0
C16: 3 | D16: 1-1 | F16: 0 | G16: 1728.55 | H16: 0 | I16: 134.46 | J16: 322.23 | K16: =SUM(F16:J16) -> 2185.24 | M16: 0 | N16: 70.652 | O16: 472.302 | P16: 77.055 | Q16: 0 | R16: =SUM(M16:Q16) -> 620.009 | T16: 0 | U16: 0 | V16: 0 | W16: 0 | X16: 0 | Y16: =SUM(T16:X16) -> 0 | AA16: 0 | AB16: 0 | AC16: 0 | AD16: 0 | AE16: 0 | AF16: =SUM(AA16:AE16) -> 0 | AH16: 0 | AI16: 0 | AJ16: 0 | AK16: 0 | AL16: 0 | AM16: =SUM(AH16:AL16) -> 0 | AO16: =AH16+AA16 -> 0 | AP16: =AI16+AB16 -> 0 | AQ16: =AJ16+AC16 -> 0 | AR16: =AK16+AD16 -> 0 | AS16: =AL16+AE16 -> 0 | AT16: =SUM(AO16:AS16) -> 0
F17: 70.652 | G17: 0 | H17: 284.34095 | I17: 0 | J17: 0 | K17: =SUM(F17:J17) -> 354.99295 | M17: 1728.55 | N17: 0 | O17: 0 | P17: 115.69 | Q17: 0 | R17: =SUM(M17:Q17) -> 1844.24 | T17: 0 | U17: 0 | V17: 4.67905 | W17: 0 | X17: 0 | Y17: =SUM(T17:X17) -> 4.67905 | AA17: 0 | AB17: 0 | AC17: 0 | AD17: 0 | AE17: 0 | AF17: =SUM(AA17:AE17) -> 0 | AH17: 0 | AI17: 0 | AJ17: 0 | AK17: 0 | AL17: 0 | AM17: =SUM(AH17:AL17) -> 0 | AO17: =AH17+AA17 -> 0 | AP17: =AI17+AB17 -> 0 | AQ17: =AJ17+AC17 -> 0 | AR17: =AK17+AD17 -> 0 | AS17: =AL17+AE17 -> 0 | AT17: =SUM(AO17:AS17) -> 0
F18: 472.302 | G18: 0 | H18: 0 | I18: 0 | J18: 0 | K18: =SUM(F18:J18) -> 472.302 | M18: 0 | N18: 284.34095 | O18: 0 | P18: 948.7083 | Q18: 0 | R18: =SUM(M18:Q18) -> 1233.0493 | T18: 0 | U18: 0 | V18: 0 | W18: 0 | X18: 0 | Y18: =SUM(T18:X18) -> 0 | AA18: 0 | AB18: 0 | AC18: 0 | AD18: 0 | AE18: 0 | AF18: =SUM(AA18:AE18) -> 0 | AH18: 0 | AI18: 0 | AJ18: 0 | AK18: 0 | AL18: 0 | AM18: =SUM(AH18:AL18) -> 0 | AO18: =AH18+AA18 -> 0 | AP18: =AI18+AB18 -> 0 | AQ18: =AJ18+AC18 -> 0 | AR18: =AK18+AD18 -> 0 | AS18: =AL18+AE18 -> 0 | AT18: =SUM(AO18:AS18) -> 0
F19: 77.055 | G19: 115.69 | H19: 948.7083 | I19: 0 | J19: 158.48 | K19: =SUM(F19:J19) -> 1299.9333 | M19: 134.46 | N19: 0 | O19: 0 | P19: 0 | Q19: 2717.39 | R19: =SUM(M19:Q19) -> 2851.85 | T19: 0 | U19: 0 | V19: 15.6117 | W19: 0 | X19: 0 | Y19: =SUM(T19:X19) -> 15.6117 | AA19: 0 | AB19: 0 | AC19: 0 | AD19: 0 | AE19: 0 | AF19: =SUM(AA19:AE19) -> 0 | AH19: 0 | AI19: 0 | AJ19: 0 | AK19: 0 | AL19: 0 | AM19: =SUM(AH19:AL19) -> 0 | AO19: =AH19+AA19 -> 0 | AP19: =AI19+AB19 -> 0 | AQ19: =AJ19+AC19 -> 0 | AR19: =AK19+AD19 -> 0 | AS19: =AL19+AE19 -> 0 | AT19: =SUM(AO19:AS19) -> 0
F20: 0 | G20: 0 | H20: 0 | I20: 2717.39 | J20: 0 | K20: =SUM(F20:J20) -> 2717.39 | M20: 322.23 | N20: 0 | O20: 0 | P20: 158.48 | Q20: 0 | R20: =SUM(M20:Q20) -> 480.71 | T20: 0 | U20: 0 | V20: 0 | W20: 0 | X20: 0 | Y20: =SUM(T20:X20) -> 0 | AA20: 0 | AB20: 0 | AC20: 0 | AD20: 0 | AE20: 0 | AF20: =SUM(AA20:AE20) -> 0 | AH20: 0 | AI20: 0 | AJ20: 0 | AK20: 0 | AL20: 0 | AM20: =SUM(AH20:AL20) -> 0 | AO20: =AH20+AA20 -> 0 | AP20: =AI20+AB20 -> 0 | AQ20: =AJ20+AC20 -> 0 | AR20: =AK20+AD20 -> 0 | AS20: =AL20+AE20 -> 0 | AT20: =SUM(AO20:AS20) -> 0
F21: =SUM(F16:F20) -> 620.009 | G21: =SUM(G16:G20) -> 1844.24 | H21: =SUM(H16:H20) -> 1233.0493 | I21: =SUM(I16:I20) -> 2851.85 | J21: =SUM(J16:J20) -> 480.71 | K21: =SUM(K16:K20) -> 7029.8582 | M21: =SUM(M16:M20) -> 2185.24 | N21: =SUM(N16:N20) -> 354.99295 | O21: =SUM(O16:O20) -> 472.302 | P21: =SUM(P16:P20) -> 1299.9333 | Q21: =SUM(Q16:Q20) -> 2717.39 | R21: =SUM(R16:R20) -> 7029.8583 | T21: =SUM(T16:T20) -> 0 | U21: =SUM(U16:U20) -> 0 | V21: =SUM(V16:V20) -> 20.29075 | W21: =SUM(W16:W20) -> 0 | X21: =SUM(X16:X20) -> 0 | Y21: =SUM(Y16:Y20) -> 20.29075 | AA21: =SUM(AA16:AA20) -> 0 | AB21: =SUM(AB16:AB20) -> 0 | AC21: =SUM(AC16:AC20) -> 0 | AD21: =SUM(AD16:AD20) -> 0 | AE21: =SUM(AE16:AE20) -> 0 | AF21: =SUM(AF16:AF20) -> 0 | AH21: =SUM(AH16:AH20) -> 0 | AI21: =SUM(AI16:AI20) -> 0 | AJ21: =SUM(AJ16:AJ20) -> 0 | AK21: =SUM(AK16:AK20) -> 0 | AL21: =SUM(AL16:AL20) -> 0 | AM21: =SUM(AM16:AM20) -> 0 | AO21: =SUM(AO16:AO20) -> 0 | AP21: =SUM(AP16:AP20) -> 0 | AQ21: =SUM(AQ16:AQ20) -> 0 | AR21: =SUM(AR16:AR20) -> 0 | AS21: =SUM(AS16:AS20) -> 0 | AT21: =SUM(AT16:AT20) -> 0
A23: 3 | C23: 2 | D23: 1-3 | F23: 0 | G23: 1728.55 | H23: 0 | I23: 134.46 | J23: 322.23 | K23: =SUM(F23:J23) -> 2185.24 | M23: 0 | N23: 70.652 | O23: 0 | P23: 77.055 | Q23: 0 | R23: =SUM(M23:Q23) -> 147.707 | T23: 0 | U23: 0 | V23: 0 | W23: 0 | X23: 0 | Y23: =SUM(T23:X23) -> 0 | AA23: 0 | AB23: 0 | AC23: 0 | AD23: 0 | AE23: 0 | AF23: =SUM(AA23:AE23) -> 0 | AH23: 0 | AI23: 0 | AJ23: 472.302 | AK23: 0 | AL23: 0 | AM23: =SUM(AH23:AL23) -> 472.302 | AO23: =AH23+AA23 -> 0 | AP23: =AI23+AB23 -> 0 | AQ23: =AJ23+AC23 -> 472.302 | AR23: =AK23+AD23 -> 0 | AS23: =AL23+AE23 -> 0 | AT23: =SUM(AO23:AS23) -> 472.302
F24: 70.652 | G24: 0 | H24: 284.34095 | I24: 0 | J24: 0 | K24: =SUM(F24:J24) -> 354.99295 | M24: 0 | N24: 0 | O24: 0 | P24: 115.69 | Q24: 0 | R24: =SUM(M24:Q24) -> 115.69 | T24: 0 | U24: 0 | V24: 0 | W24: 0 | X24: 0 | Y24: =SUM(T24:X24) -> 0 | AA24: 0 | AB24: 0 | AC24: 0 | AD24: 0 | AE24: 0 | AF24: =SUM(AA24:AE24) -> 0 | AH24: 1728.55 | AI24: 0 | AJ24: 0 | AK24: 0 | AL24: 0 | AM24: =SUM(AH24:AL24) -> 1728.55 | AO24: =AH24+AA24 -> 1728.55 | AP24: =AI24+AB24 -> 0 | AQ24: =AJ24+AC24 -> 0 | AR24: =AK24+AD24 -> 0 | AS24: =AL24+AE24 -> 0 | AT24: =SUM(AO24:AS24) -> 1728.55
F25: 472.302 | G25: 0 | H25: 0 | I25: 0 | J25: 0 | K25: =SUM(F25:J25) -> 472.302 | M25: 0 | N25: 284.34095 | O25: 0 | P25: 948.7083 | Q25: 0 | R25: =SUM(M25:Q25) -> 1233.0493 | T25: 0 | U25: 0 | V25: 0 | W25: 0 | X25: 0 | Y25: =SUM(T25:X25) -> 0 | AA25: 0 | AB25: 0 | AC25: 0 | AD25: 0 | AE25: 0 | AF25: =SUM(AA25:AE25) -> 0 | AH25: 0 | AI25: 0 | AJ25: 0 | AK25: 0 | AL25: 0 | AM25: =SUM(AH25:AL25) -> 0 | AO25: =AH25+AA25 -> 0 | AP25: =AI25+AB25 -> 0 | AQ25: =AJ25+AC25 -> 0 | AR25: =AK25+AD25 -> 0 | AS25: =AL25+AE25 -> 0 | AT25: =SUM(AO25:AS25) -> 0
F26: 77.055 | G26: 115.69 | H26: 948.7083 | I26: 0 | J26: 158.48 | K26: =SUM(F26:J26) -> 1299.9333 | M26: 0 | N26: 0 | O26: 0 | P26: 0 | Q26: 2717.39 | R26: =SUM(M26:Q26) -> 2717.39 | T26: 0 | U26: 0 | V26: 0 | W26: 0 | X26: 0 | Y26: =SUM(T26:X26) -> 0 | AA26: 0 | AB26: 0 | AC26: 0 | AD26: 0 | AE26: 0 | AF26: =SUM(AA26:AE26) -> 0 | AH26: 134.46 | AI26: 0 | AJ26: 0 | AK26: 0 | AL26: 0 | AM26: =SUM(AH26:AL26) -> 134.46 | AO26: =AH26+AA26 -> 134.46 | AP26: =AI26+AB26 -> 0 | AQ26: =AJ26+AC26 -> 0 | AR26: =AK26+AD26 -> 0 | AS26: =AL26+AE26 -> 0 | AT26: =SUM(AO26:AS26) -> 134.46
F27: 0 | G27: 0 | H27: 0 | I27: 2717.39 | J27: 0 | K27: =SUM(F27:J27) -> 2717.39 | M27: 0 | N27: 0 | O27: 0 | P27: 158.48 | Q27: 0 | R27: =SUM(M27:Q27) -> 158.48 | T27: 0 | U27: 0 | V27: 0 | W27: 0 | X27: 0 | Y27: =SUM(T27:X27) -> 0 | AA27: 0 | AB27: 0 | AC27: 0 | AD27: 0 | AE27: 0 | AF27: =SUM(AA27:AE27) -> 0 | AH27: 322.23 | AI27: 0 | AJ27: 0 | AK27: 0 | AL27: 0 | AM27: =SUM(AH27:AL27) -> 322.23 | AO27: =AH27+AA27 -> 322.23 | AP27: =AI27+AB27 -> 0 | AQ27: =AJ27+AC27 -> 0 | AR27: =AK27+AD27 -> 0 | AS27: =AL27+AE27 -> 0 | AT27: =SUM(AO27:AS27) -> 322.23
F28: =SUM(F23:F27) -> 620.009 | G28: =SUM(G23:G27) -> 1844.24 | H28: =SUM(H23:H27) -> 1233.0493 | I28: =SUM(I23:I27) -> 2851.85 | J28: =SUM(J23:J27) -> 480.71 | K28: =SUM(K23:K27) -> 7029.8582 | M28: =SUM(M23:M27) -> 0 | N28: =SUM(N23:N27) -> 354.99295 | O28: =SUM(O23:O27) -> 0 | P28: =SUM(P23:P27) -> 1299.9333 | Q28: =SUM(Q23:Q27) -> 2717.39 | R28: =SUM(R23:R27) -> 4372.3162 | T28: =SUM(T23:T27) -> 0 | U28: =SUM(U23:U27) -> 0 | V28: =SUM(V23:V27) -> 0 | W28: =SUM(W23:W27) -> 0 | X28: =SUM(X23:X27) -> 0 | Y28: =SUM(Y23:Y27) -> 0 | AA28: =SUM(AA23:AA27) -> 0 | AB28: =SUM(AB23:AB27) -> 0 | AC28: =SUM(AC23:AC27) -> 0 | AD28: =SUM(AD23:AD27) -> 0 | AE28: =SUM(AE23:AE27) -> 0 | AF28: =SUM(AF23:AF27) -> 0 | AH28: =SUM(AH23:AH27) -> 2185.24 | AI28: =SUM(AI23:AI27) -> 0 | AJ28: =SUM(AJ23:AJ27) -> 472.302 | AK28: =SUM(AK23:AK27) -> 0 | AL28: =SUM(AL23:AL27) -> 0 | AM28: =SUM(AM23:AM27) -> 2657.542 | AO28: =SUM(AO23:AO27) -> 2185.24 | AP28: =SUM(AP23:AP27) -> 0 | AQ28: =SUM(AQ23:AQ27) -> 472.302 | AR28: =SUM(AR23:AR27) -> 0 | AS28: =SUM(AS23:AS27) -> 0 | AT28: =SUM(AT23:AT27) -> 2657.542

Sheet BB之过程-theta_Shock_exBI_t=0_0313
A1: 子过程 | B1: tau | C1: t | D1: id | E1: name | F1: A_R | G1: A_Q | H1: A_P | I1: A_other | J1: A_exBI | K1: A_BI_all | L1: A_all | M1: Z_D | N1: Z_other | O1: Z_exBI | P1: Z_BI_all | Q1: Z_all | R1: E_all | S1: Bo_D | T1: Li_P | U1: Lo_BI_all | V1: Li_BI_all | W1: Bi_BI_all | X1: Bo_BI_all | Y1: Shock_B_def_t | Z1: Shock_B_run_t | AA1: BB.Shock_P_def_t | AB1: BB.Shock_D_def_s | AC1: BB.Shock_D_run_t | AD1: BB.Shock_P_run_s | AE1: BB.Shock_BI_def_s | AF1: BB.Shock_BI_def_t | AG1: BB.Shock_BI_run_ilq_s | AH1: BB.Shock_BI_run_ilq_t | AI1: BB.Shock_BI_run_br_s | AJ1: BB.Shock_BI_run_br_t | AK1: BB.Shock_BI_run_s | AL1: BB.Shock_BI_run_t | AM1: BB.Shock_BI_s | AN1: BB.Shock_BI_t
A2: 2 | B2: 1 | C2: 0 | D2: 1 | E2: BK1 | F2: 0 | G2: 477.125 | H2: 1631.73 | I2: 0 | J2: =F2+G2+H2+I2 -> 2108.855 | K2: 2185.24 | L2: =J2+K2 -> 4294.095 | M2: 3160.99 | N2: 0 | O2: =M2+N2 -> 3160.99 | P2: 959.6 | Q2: =P2+O2 -> 4120.59 | R2: =MAX(L2-Q2,0) -> 173.505 | S2: 0 | T2: 0 | U2: 0 | V2: 0 | W2: 0 | X2: 0 | Y2: =AA2+AF2 -> 0 | Z2: =AC2+AL2 -> 0 | AA2: 0 | AB2: 0 | AC2: 0 | AD2: 0 | AE2: 0 | AF2: 0 | AG2: 0 | AH2: 0 | AI2: 0 | AJ2: 0 | AK2: =AG2+AI2 -> 0 | AL2: =AH2+AJ2 -> 0 | AM2: =AE2+AK2 -> 0 | AN2: =AF2+AL2 -> 0
D3: 2 | E3: BK2 | F3: 0 | G3: 587.693 | H3: 4303.24 | I3: 0 | J3: =F3+G3+H3+I3 -> 4890.933 | K3: 398.37 | L3: =J3+K3 -> 5289.303 | M3: 3231.37 | N3: 0 | O3: =M3+N3 -> 3231.37 | P3: 1844.24 | Q3: =P3+O3 -> 5075.61 | R3: =MAX(L3-Q3,0) -> 213.693 | S3: 0 | T3: 0 | U3: 0 | V3: 0 | W3: 0 | X3: 0 | Y3: =AA3+AF3 -> 0 | Z3: =AC3+AL3 -> 0 | AA3: 0 | AB3: 0 | AC3: 0 | AD3: 0 | AE3: 0 | AF3: 0 | AG3: 0 | AH3: 0 | AI3: 0 | AJ3: 0 | AK3: =AG3+AI3 -> 0 | AL3: =AH3+AJ3 -> 0 | AM3: =AE3+AK3 -> 0 | AN3: =AF3+AL3 -> 0
D4: 3 | E4: BK3 | F4: 0 | G4: 513.847 | H4: 3379.72 | I4: 0 | J4: =F4+G4+H4+I4 -> 3893.567 | K4: 730.99 | L4: =J4+K4 -> 4624.557 | M4: 3184.36 | N4: 0 | O4: =M4+N4 -> 3184.36 | P4: 1253.34 | Q4: =P4+O4 -> 4437.7 | R4: =MAX(L4-Q4,0) -> 186.857 | S4: 0 | T4: 0 | U4: 0 | V4: 0 | W4: 0 | X4: 0 | Y4: =AA4+AF4 -> 0 | Z4: =AC4+AL4 -> 0 | AA4: 0 | AB4: 0 | AC4: 0 | AD4: 0 | AE4: 0 | AF4: 0 | AG4: 0 | AH4: 0 | AI4: 0 | AJ4: 0 | AK4: =AG4+AI4 -> 0 | AL4: =AH4+AJ4 -> 0 | AM4: =AE4+AK4 -> 0 | AN4: =AF4+AL4 -> 0
D5: 4 | E5: BK4 | F5: 0 | G5: 713.662 | H5: 4351.47 | I5: 0 | J5: =F5+G5+H5+I5 -> 5065.132 | K5: 1357.75 | L5: =J5+K5 -> 6422.882 | M5: 3311.51 | N5: 0 | O5: =M5+N5 -> 3311.51 | P5: 2851.85 | Q5: =P5+O5 -> 6163.36 | R5: =MAX(L5-Q5,0) -> 259.522 | S5: 0 | T5: 0 | U5: 0 | V5: 0 | W5: 0 | X5: 0 | Y5: =AA5+AF5 -> 0 | Z5: =AC5+AL5 -> 0 | AA5: 0 | AB5: 0 | AC5: 0 | AD5: 0 | AE5: 0 | AF5: 0 | AG5: 0 | AH5: 0 | AI5: 0 | AJ5: 0 | AK5: =AG5+AI5 -> 0 | AL5: =AH5+AJ5 -> 0 | AM5: =AE5+AK5 -> 0 | AN5: =AF5+AL5 -> 0
D6: 5 | E6: BK5 | F6: 0 | G6: 417.257 | H6: 620.69 | I6: 0 | J6: =F6+G6+H6+I6 -> 1037.947 | K6: 2717.39 | L6: =J6+K6 -> 3755.337 | M6: 3122.9 | N6: 0 | O6: =M6+N6 -> 3122.9 | P6: 480.71 | Q6: =P6+O6 -> 3603.61 | R6: =MAX(L6-Q6,0) -> 151.727 | S6: 0 | T6: 0 | U6: 0 | V6: 0 | W6: 0 | X6: 0 | Y6: =AA6+AF6 -> 0 | Z6: =AC6+AL6 -> 0 | AA6: 0 | AB6: 0 | AC6: 0 | AD6: 0 | AE6: 0 | AF6: 0 | AG6: 0 | AH6: 0 | AI6: 0 | AJ6: 0 | AK6: =AG6+AI6 -> 0 | AL6: =AH6+AJ6 -> 0 | AM6: =AE6+AK6 -> 0 | AN6: =AF6+AL6 -> 0
F7: =SUM(F2:F6) -> 0 | G7: =SUM(G2:G6) -> 2709.584 | H7: =SUM(H2:H6) -> 14286.85 | I7: =SUM(I2:I6) -> 0 | J7: =SUM(J2:J6) -> 16996.434 | K7: =SUM(K2:K6) -> 7389.74 | L7: =SUM(L2:L6) -> 24386.174 | M7: =SUM(M2:M6) -> 16011.13 | ... AN7: =SUM(AN2:AN6) -> 0
A9: 2 | B9: 1 | C9: 1 | D9: 1 | E9: BK1 | F9: 0 | G9: 477.125 | H9: 1631.73 | I9: 0 | J9: =F9+G9+H9+I9 -> 2108.855 | K9: 2185.24 | L9: =J9+K9 -> 4294.095 | M9: 3160.99 | N9: 0 | O9: =M9+N9 -> 3160.99 | P9: 959.6 | Q9: =P9+O9 -> 4120.59 | R9: =MAX(L9-Q9,0) -> 173.505 | S9: 0 | T9: 0 | U9: 0 | V9: 0 | W9: 0 | X9: 0 | Y9: =AA9+AF9 -> 0 | Z9: =AC9+AL9 -> 3160.99 | AA9: 0 | AB9: 0 | AC9: 3160.99 | AD9: 0 | AE9: 0 | AF9: 0 | AG9: 0 | AH9: 0 | AI9: 0 | AJ9: 0 | AK9: =AG9+AI9 -> 0 | AL9: =AH9+AJ9 -> 0 | AM9: =AE9+AK9 -> 0 | AN9: =AF9+AL9 -> 0
D10: 2 | E10: BK2 | F10: 0 | G10: 587.693 | H10: 4303.24 | I10: 0 | J10: =F10+G10+H10+I10 -> 4890.933 | K10: 398.37 | L10: =J10+K10 -> 5289.303 | M10: 3231.37 | N10: 0 | O10: =M10+N10 -> 3231.37 | P10: 1844.24 | Q10: =P10+O10 -> 5075.61 | R10: =MAX(L10-Q10,0) -> 213.693 | S10: 0 | T10: 0 | U10: 0 | V10: 0 | W10: 0 | X10: 0 | Y10: =AA10+AF10 -> 0 | Z10: =AC10+AL10 -> 0 | AA10: 0 | AB10: 0 | AC10: 0 | AD10: 0 | AE10: 0 | AF10: 0 | AG10: 0 | AH10: 0 | AI10: 0 | AJ10: 0 | AK10: =AG10+AI10 -> 0 | AL10: =AH10+AJ10 -> 0 | AM10: =AE10+AK10 -> 0 | AN10: =AF10+AL10 -> 0
D11: 3 | E11: BK3 | F11: 0 | G11: 513.847 | H11: 3379.72 | I11: 0 | J11: =F11+G11+H11+I11 -> 3893.567 | K11: 730.99 | L11: =J11+K11 -> 4624.557 | M11: 3184.36 | N11: 0 | O11: =M11+N11 -> 3184.36 | P11: 1253.34 | Q11: =P11+O11 -> 4437.7 | R11: =MAX(L11-Q11,0) -> 186.857 | S11: 0 | T11: 0 | U11: 0 | V11: 0 | W11: 0 | X11: 0 | Y11: =AA11+AF11 -> 0 | Z11: =AC11+AL11 -> 0 | AA11: 0 | AB11: 0 | AC11: 0 | AD11: 0 | AE11: 0 | AF11: 0 | AG11: 0 | AH11: 0 | AI11: 0 | AJ11: 0 | AK11: =AG11+AI11 -> 0 | AL11: =AH11+AJ11 -> 0 | AM11: =AE11+AK11 -> 0 | AN11: =AF11+AL11 -> 0
D12: 4 | E12: BK4 | F12: 0 | G12: 713.662 | H12: 4351.47 | I12: 0 | J12: =F12+G12+H12+I12 -> 5065.132 | K12: 1357.75 | L12: =J12+K12 -> 6422.882 | M12: 3311.51 | N12: 0 | O12: =M12+N12 -> 3311.51 | P12: 2851.85 | Q12: =P12+O12 -> 6163.36 | R12: =MAX(L12-Q12,0) -> 259.522 | S12: 0 | T12: 0 | U12: 0 | V12: 0 | W12: 0 | X12: 0 | Y12: =AA12+AF12 -> 0 | Z12: =AC12+AL12 -> 0 | AA12: 0 | AB12: 0 | AC12: 0 | AD12: 0 | AE12: 0 | AF12: 0 | AG12: 0 | AH12: 0 | AI12: 0 | AJ12: 0 | AK12: =AG12+AI12 -> 0 | AL12: =AH12+AJ12 -> 0 | AM12: =AE12+AK12 -> 0 | AN12: =AF12+AL12 -> 0
D13: 5 | E13: BK5 | F13: 0 | G13: 417.257 | H13: 620.69 | I13: 0 | J13: =F13+G13+H13+I13 -> 1037.947 | K13: 2717.39 | L13: =J13+K13 -> 3755.337 | M13: 3122.9 | N13: 0 | O13: =M13+N13 -> 3122.9 | P13: 480.71 | Q13: =P13+O13 -> 3603.61 | R13: =MAX(L13-Q13,0) -> 151.727 | S13: 0 | T13: 0 | U13: 0 | V13: 0 | W13: 0 | X13: 0 | Y13: =AA13+AF13 -> 0 | Z13: =AC13+AL13 -> 0 | AA13: 0 | AB13: 0 | AC13: 0 | AD13: 0 | AE13: 0 | AF13: 0 | AG13: 0 | AH13: 0 | AI13: 0 | AJ13: 0 | AK13: =AG13+AI13 -> 0 | AL13: =AH13+AJ13 -> 0 | AM13: =AE13+AK13 -> 0 | AN13: =AF13+AL13 -> 0
F14: =SUM(F9:F13) -> 0 | G14: =SUM(G9:G13) -> 2709.584 | H14: =SUM(H9:H13) -> 14286.85 | I14: =SUM(I9:I13) -> 0 | J14: =SUM(J9:J13) -> 16996.434 | K14: =SUM(K9:K13) -> 7389.74 | L14: =SUM(L9:L13) -> 24386.174 | M14: =SUM(M9:M13) -> 16011.13 | ... AN14: =SUM(AN9:AN13) -> 0
A16: 2 | B16: 2 | C16: 1 | D16: 1 | E16: BK1 | F16: 0 | G16: 477.125 | H16: 1631.73 | I16: 0 | J16: =F16+G16+H16+I16 -> 2108.855 | K16: 2185.24 | L16: =J16+K16 -> 4294.095 | M16: 3160.99 | N16: 0 | O16: =M16+N16 -> 3160.99 | P16: 959.6 | Q16: =P16+O16 -> 4120.59 | R16: =MAX(L16-Q16,0) -> 173.505 | S16: 0 | T16: 0 | U16: 0 | V16: 0 | W16: 0 | X16: 0 | Y16: =AA16+AF16 -> 0 | Z16: =AC16+AL16 -> 3160.99 | AA16: 0 | AB16: 0 | AC16: 3160.99 | AD16: 1147.335 | AE16: 0 | AF16: 0 | AG16: 1536.53 | AH16: 0 | AI16: 0 | AJ16: 0 | AK16: =AG16+AI16 -> 1536.53 | AL16: =AH16+AJ16 -> 0 | AM16: =AE16+AK16 -> 1536.53 | AN16: =AF16+AL16 -> 0
D17: 2 | E17: BK2 | F17: 0 | G17: 587.693 | H17: 4303.24 | I17: 0 | J17: =F17+G17+H17+I17 -> 4890.933 | K17: 398.37 | L17: =J17+K17 -> 5289.303 | M17: 3231.37 | N17: 0 | O17: =M17+N17 -> 3231.37 | P17: 1844.24 | Q17: =P17+O17 -> 5075.61 | R17: =MAX(L17-Q17,0) -> 213.693 | S17: 0 | T17: 0 | U17: 0 | V17: 0 | W17: 0 | X17: 0 | Y17: =AA17+AF17 -> 0 | Z17: =AC17+AL17 -> 1215.41 | AA17: 0 | AB17: 0 | AC17: 0 | AD17: 0 | AE17: 0 | AF17: 0 | AG17: 0 | AH17: 1215.41 | AI17: 0 | AJ17: 0 | AK17: =AG17+AI17 -> 0 | AL17: =AH17+AJ17 -> 1215.41 | AM17: =AE17+AK17 -> 0 | AN17: =AF17+AL17 -> 1215.41
D18: 3 | E18: BK3 | F18: 0 | G18: 513.847 | H18: 3379.72 | I18: 0 | J18: =F18+G18+H18+I18 -> 3893.567 | K18: 730.99 | L18: =J18+K18 -> 4624.557 | M18: 3184.36 | N18: 0 | O18: =M18+N18 -> 3184.36 | P18: 1253.34 | Q18: =P18+O18 -> 4437.7 | R18: =MAX(L18-Q18,0) -> 186.857 | S18: 0 | T18: 0 | U18: 0 | V18: 0 | W18: 0 | X18: 0 | Y18: =AA18+AF18 -> 0 | Z18: =AC18+AL18 -> 0 | AA18: 0 | AB18: 0 | AC18: 0 | AD18: 0 | AE18: 0 | AF18: 0 | AG18: 0 | AH18: 0 | AI18: 0 | AJ18: 0 | AK18: =AG18+AI18 -> 0 | AL18: =AH18+AJ18 -> 0 | AM18: =AE18+AK18 -> 0 | AN18: =AF18+AL18 -> 0
D19: 4 | E19: BK4 | F19: 0 | G19: 713.662 | H19: 4351.47 | I19: 0 | J19: =F19+G19+H19+I19 -> 5065.132 | K19: 1357.75 | L19: =J19+K19 -> 6422.882 | M19: 3311.51 | N19: 0 | O19: =M19+N19 -> 3311.51 | P19: 2851.85 | Q19: =P19+O19 -> 6163.36 | R19: =MAX(L19-Q19,0) -> 259.522 | S19: 0 | T19: 0 | U19: 0 | V19: 0 | W19: 0 | X19: 0 | Y19: =AA19+AF19 -> 0 | Z19: =AC19+AL19 -> 94.5442 | AA19: 0 | AB19: 0 | AC19: 0 | AD19: 0 | AE19: 0 | AF19: 0 | AG19: 0 | AH19: 94.5442 | AI19: 0 | AJ19: 0 | AK19: =AG19+AI19 -> 0 | AL19: =AH19+AJ19 -> 94.5442 | AM19: =AE19+AK19 -> 0 | AN19: =AF19+AL19 -> 94.5442
D20: 5 | E20: BK5 | F20: 0 | G20: 417.257 | H20: 620.69 | I20: 0 | J20: =F20+G20+H20+I20 -> 1037.947 | K20: 2717.39 | L20: =J20+K20 -> 3755.337 | M20: 3122.9 | N20: 0 | O20: =M20+N20 -> 3122.9 | P20: 480.71 | Q20: =P20+O20 -> 3603.61 | R20: =MAX(L20-Q20,0) -> 151.727 | S20: 0 | T20: 0 | U20: 0 | V20: 0 | W20: 0 | X20: 0 | Y20: =AA20+AF20 -> 0 | Z20: =AC20+AL20 -> 226.573 | AA20: 0 | AB20: 0 | AC20: 0 | AD20: 0 | AE20: 0 | AF20: 0 | AG20: 0 | AH20: 226.573 | AI20: 0 | AJ20: 0 | AK20: =AG20+AI20 -> 0 | AL20: =AH20+AJ20 -> 226.573 | AM20: =AE20+AK20 -> 0 | AN20: =AF20+AL20 -> 226.573
F21: =SUM(F16:F20) -> 0 | G21: =SUM(G16:G20) -> 2709.584 | H21: =SUM(H16:H20) -> 14286.85 | I21: =SUM(I16:I20) -> 0 | J21: =SUM(J16:J20) -> 16996.434 | K21: =SUM(K16:K20) -> 7389.74 | L21: =SUM(L16:L20) -> 24386.174 | M21: =SUM(M16:M20) -> 16011.13 | ... AN21: =SUM(AN16:AN20) -> 1536.5272
A23: 2 | B23: 2 | C23: 2 | D23: 1 | E23: BK1 | F23: 0 | G23: 477.125 | H23: 1631.73 | I23: 0 | J23: =F23+G23+H23+I23 -> 2108.855 | K23: 2185.24 | L23: =J23+K23 -> 4294.095 | M23: 3160.99 | N23: 0 | O23: =M23+N23 -> 3160.99 | P23: 959.6 | Q23: =P23+O23 -> 4120.59 | R23: =MAX(L23-Q23,0) -> 173.505 | S23: 477.125 | T23: 1147.335 | U23: 0 | V23: 908.8102 | W23: 0 | X23: 0 | Y23: =AA23+AF23 -> 0 | Z23: =AC23+AL23 -> 3160.99 | AA23: 0 | AB23: 0 | AC23: 3160.99 | AD23: 1147.335 | AE23: 0 | AF23: 0 | AG23: 1536.53 | AH23: 0 | AI23: 0 | AJ23: 0 | AK23: =AG23+AI23 -> 1536.53 | AL23: =AH23+AJ23 -> 0 | AM23: =AE23+AK23 -> 1536.53 | AN23: =AF23+AL23 -> 0
D24: 2 | E24: BK2 | F24: 0 | G24: 587.693 | H24: 4303.24 | I24: 0 | J24: =F24+G24+H24+I24 -> 4890.933 | K24: 398.37 | L24: =J24+K24 -> 5289.303 | M24: 3231.37 | N24: 0 | O24: =M24+N24 -> 3231.37 | P24: 1844.24 | Q24: =P24+O24 -> 5075.61 | R24: =MAX(L24-Q24,0) -> 213.693 | S24: 0 | T24: 0 | U24: 0 | V24: 0 | W24: 0 | X24: 587.693 | Y24: =AA24+AF24 -> 0 | Z24: =AC24+AL24 -> 1215.41 | AA24: 0 | AB24: 0 | AC24: 0 | AD24: 0 | AE24: 0 | AF24: 0 | AG24: 0 | AH24: 1215.41 | AI24: 0 | AJ24: 0 | AK24: =AG24+AI24 -> 0 | AL24: =AH24+AJ24 -> 1215.41 | AM24: =AE24+AK24 -> 0 | AN24: =AF24+AL24 -> 1215.41
D25: 3 | E25: BK3 | F25: 0 | G25: 513.847 | H25: 3379.72 | I25: 0 | J25: =F25+G25+H25+I25 -> 3893.567 | K25: 730.99 | L25: =J25+K25 -> 4624.557 | M25: 3184.36 | N25: 0 | O25: =M25+N25 -> 3184.36 | P25: 1253.34 | Q25: =P25+O25 -> 4437.7 | R25: =MAX(L25-Q25,0) -> 186.857 | S25: 0 | T25: 0 | U25: 0 | V25: 0 | W25: 0 | X25: 0 | Y25: =AA25+AF25 -> 0 | Z25: =AC25+AL25 -> 0 | AA25: 0 | AB25: 0 | AC25: 0 | AD25: 0 | AE25: 0 | AF25: 0 | AG25: 0 | AH25: 0 | AI25: 0 | AJ25: 0 | AK25: =AG25+AI25 -> 0 | AL25: =AH25+AJ25 -> 0 | AM25: =AE25+AK25 -> 0 | AN25: =AF25+AL25 -> 0
D26: 4 | E26: BK4 | F26: 0 | G26: 713.662 | H26: 4351.47 | I26: 0 | J26: =F26+G26+H26+I26 -> 5065.132 | K26: 1357.75 | L26: =J26+K26 -> 6422.882 | M26: 3311.51 | N26: 0 | O26: =M26+N26 -> 3311.51 | P26: 2851.85 | Q26: =P26+O26 -> 6163.36 | R26: =MAX(L26-Q26,0) -> 259.522 | S26: 0 | T26: 0 | U26: 0 | V26: 0 | W26: 0 | X26: 94.5442 | Y26: =AA26+AF26 -> 0 | Z26: =AC26+AL26 -> 94.5442 | AA26: 0 | AB26: 0 | AC26: 0 | AD26: 0 | AE26: 0 | AF26: 0 | AG26: 0 | AH26: 94.5442 | AI26: 0 | AJ26: 0 | AK26: =AG26+AI26 -> 0 | AL26: =AH26+AJ26 -> 94.5442 | AM26: =AE26+AK26 -> 0 | AN26: =AF26+AL26 -> 94.5442
D27: 5 | E27: BK5 | F27: 0 | G27: 417.257 | H27: 620.69 | I27: 0 | J27: =F27+G27+H27+I27 -> 1037.947 | K27: 2717.39 | L27: =J27+K27 -> 3755.337 | M27: 3122.9 | N27: 0 | O27: =M27+N27 -> 3122.9 | P27: 480.71 | Q27: =P27+O27 -> 3603.61 | R27: =MAX(L27-Q27,0) -> 151.727 | S27: 0 | T27: 0 | U27: 0 | V27: 0 | W27: 0 | X27: 226.573 | Y27: =AA27+AF27 -> 0 | Z27: =AC27+AL27 -> 226.573 | AA27: 0 | AB27: 0 | AC27: 0 | AD27: 0 | AE27: 0 | AF27: 0 | AG27: 0 | AH27: 226.573 | AI27: 0 | AJ27: 0 | AK27: =AG27+AI27 -> 0 | AL27: =AH27+AJ27 -> 226.573 | AM27: =AE27+AK27 -> 0 | AN27: =AF27+AL27 -> 226.573
F28: =SUM(F23:F27) -> 0 | G28: =SUM(G23:G27) -> 2709.584 | H28: =SUM(H23:H27) -> 14286.85 | I28: =SUM(I23:I27) -> 0 | J28: =SUM(J23:J27) -> 16996.434 | K28: =SUM(K23:K27) -> 7389.74 | L28: =SUM(L23:L27) -> 24386.174 | M28: =SUM(M23:M27) -> 16011.13 | ... AN28: =SUM(AN23:AN27) -> 1536.5272
A30: 2 | B30: 2 | C30: 3 | D30: 1 | E30: BK1 | F30: 0 | G30: 2056.145 | H30: 484.39502 | I30: 0 | J30: =F30+G30+H30+I30 -> 2540.54 | K30: 1276.4329 | L30: =J30+K30 -> 3816.9729 | M30: 2683.865 | N30: 0 | O30: =M30+N30 -> 2683.865 | P30: 959.6 | Q30: =P30+O30 -> 3643.465 | R30: =MAX(L30-Q30,0) -> 173.50792 | S30: 477.125 | T30: 1147.335 | U30: 0 | V30: 908.8102 | W30: 0 | X30: 0 | Y30: =AA30+AF30 -> 0 | Z30: =AC30+AL30 -> 2683.865 | AA30: 0 | AB30: 0 | AC30: 2683.865 | AD30: 0 | AE30: 0 | AF30: 0 | AG30: 627.7199 | AH30: 0 | AI30: 0 | AJ30: 0 | AK30: =AG30+AI30 -> 627.7199 | AL30: =AH30+AJ30 -> 0 | AM30: =AE30+AK30 -> 627.7199 | AN30: =AF30+AL30 -> 0
D31: 2 | E31: BK2 | F31: 0 | G31: 0 | H31: 4303.24 | I31: 0 | J31: =F31+G31+H31+I31 -> 4303.24 | K31: 398.37 | L31: =J31+K31 -> 4701.61 | M31: 3231.37 | N31: 0 | O31: =M31+N31 -> 3231.37 | P31: 1256.55 | Q31: =P31+O31 -> 4487.92 | R31: =MAX(L31-Q31,0) -> 213.69 | S31: 0 | T31: 0 | U31: 0 | V31: 0 | W31: 0 | X31: 587.693 | Y31: =AA31+AF31 -> 0 | Z31: =AC31+AL31 -> 627.72 | AA31: 0 | AB31: 0 | AC31: 0 | AD31: 0 | AE31: 0 | AF31: 0 | AG31: 0 | AH31: 627.72 | AI31: 0 | AJ31: 0 | AK31: =AG31+AI31 -> 0 | AL31: =AH31+AJ31 -> 627.72 | AM31: =AE31+AK31 -> 0 | AN31: =AF31+AL31 -> 627.72
D32: 3 | E32: BK3 | F32: 0 | G32: 513.847 | H32: 3379.72 | I32: 0 | J32: =F32+G32+H32+I32 -> 3893.567 | K32: 730.99 | L32: =J32+K32 -> 4624.557 | M32: 3184.36 | N32: 0 | O32: =M32+N32 -> 3184.36 | P32: 1253.34 | Q32: =P32+O32 -> 4437.7 | R32: =MAX(L32-Q32,0) -> 186.857 | S32: 0 | T32: 0 | U32: 0 | V32: 0 | W32: 0 | X32: 0 | Y32: =AA32+AF32 -> 0 | Z32: =AC32+AL32 -> 0 | AA32: 0 | AB32: 0 | AC32: 0 | AD32: 0 | AE32: 0 | AF32: 0 | AG32: 0 | AH32: 0 | AI32: 0 | AJ32: 0 | AK32: =AG32+AI32 -> 0 | AL32: =AH32+AJ32 -> 0 | AM32: =AE32+AK32 -> 0 | AN32: =AF32+AL32 -> 0
D33: 4 | E33: BK4 | F33: 0 | G33: 619.11774 | H33: 4351.47 | I33: 0 | J33: =F33+G33+H33+I33 -> 4970.5877 | K33: 1357.75 | L33: =J33+K33 -> 6328.3377 | M33: 3311.51 | N33: 0 | O33: =M33+N33 -> 3311.51 | P33: 2757.3058 | Q33: =P33+O33 -> 6068.8158 | R33: =MAX(L33-Q33,0) -> 259.52194 | S33: 0 | T33: 0 | U33: 0 | V33: 0 | W33: 0 | X33: 94.5442 | Y33: =AA33+AF33 -> 0 | Z33: =AC33+AL33 -> 0 | AA33: 0 | AB33: 0 | AC33: 0 | AD33: 0 | AE33: 0 | AF33: 0 | AG33: 0 | AH33: 0 | AI33: 0 | AJ33: 0 | AK33: =AG33+AI33 -> 0 | AL33: =AH33+AJ33 -> 0 | AM33: =AE33+AK33 -> 0 | AN33: =AF33+AL33 -> 0
D34: 5 | E34: BK5 | F34: 0 | G34: 190.68411 | H34: 620.69 | I34: 0 | J34: =F34+G34+H34+I34 -> 811.37411 | K34: 2717.39 | L34: =J34+K34 -> 3528.7641 | M34: 3122.9 | N34: 0 | O34: =M34+N34 -> 3122.9 | P34: 254.1371 | Q34: =P34+O34 -> 3377.0371 | R34: =MAX(L34-Q34,0) -> 151.72701 | S34: 0 | T34: 0 | U34: 0 | V34: 0 | W34: 0 | X34: 226.573 | Y34: =AA34+AF34 -> 0 | Z34: =AC34+AL34 -> 0 | AA34: 0 | AB34: 0 | AC34: 0 | AD34: 0 | AE34: 0 | AF34: 0 | AG34: 0 | AH34: 0 | AI34: 0 | AJ34: 0 | AK34: =AG34+AI34 -> 0 | AL34: =AH34+AJ34 -> 0 | AM34: =AE34+AK34 -> 0 | AN34: =AF34+AL34 -> 0
F35: =SUM(F30:F34) -> 0 | G35: =SUM(G30:G34) -> 3379.7939 | H35: =SUM(H30:H34) -> 13139.515 | I35: =SUM(I30:I34) -> 0 | J35: =SUM(J30:J34) -> 16519.309 | K35: =SUM(K30:K34) -> 6480.9329 | L35: =SUM(L30:L34) -> 23000.242 | M35: =SUM(M30:M34) -> 15534.005 | ... AN35: =SUM(AN30:AN34) -> 627.72
A37: 2 | B37: 3 | C37: 1 | D37: 1 | E37: BK1 | F37: 0 | G37: 2056.145 | H37: 484.39502 | I37: 0 | J37: =F37+G37+H37+I37 -> 2540.54 | K37: 1276.4329 | L37: =J37+K37 -> 3816.9729 | M37: 2683.865 | N37: 0 | O37: =M37+N37 -> 2683.865 | P37: 959.6 | Q37: =P37+O37 -> 3643.465 | R37: =MAX(L37-Q37,0) -> 173.50792 | S37: 477.125 | T37: 1147.335 | U37: 0 | V37: 908.8102 | W37: 0 | X37: 0 | Y37: =AA37+AF37 -> 0 | Z37: =AC37+AL37 -> 2698.4645 | AA37: 0 | AB37: 0 | AC37: 2683.865 | AD37: 0 | AE37: 0 | AF37: 0 | AG37: 455.03705 | AH37: 14.599504 | AI37: 0 | AJ37: 0 | AK37: =AG37+AI37 -> 455.03705 | AL37: =AH37+AJ37 -> 14.599504 | AM37: =AE37+AK37 -> 455.03705 | AN37: =AF37+AL37 -> 14.599504
D38: 2 | E38: BK2 | F38: 0 | G38: 0 | H38: 4303.24 | I38: 0 | J38: =F38+G38+H38+I38 -> 4303.24 | K38: 398.37 | L38: =J38+K38 -> 4701.61 | M38: 3231.37 | N38: 0 | O38: =M38+N38 -> 3231.37 | P38: 1256.55 | Q38: =P38+O38 -> 4487.92 | R38: =MAX(L38-Q38,0) -> 213.69 | S38: 0 | T38: 0 | U38: 0 | V38: 0 | W38: 0 | X38: 587.693 | Y38: =AA38+AF38 -> 0 | Z38: =AC38+AL38 -> 406.7064 | AA38: 0 | AB38: 0 | AC38: 0 | AD38: 0 | AE38: 0 | AF38: 0 | AG38: 53.187054 | AH38: 406.7064 | AI38: 0 | AJ38: 0 | AK38: =AG38+AI38 -> 53.187054 | AL38: =AH38+AJ38 -> 406.7064 | AM38: =AE38+AK38 -> 53.187054 | AN38: =AF38+AL38 -> 406.7064
D39: 3 | E39: BK3 | F39: 0 | G39: 513.847 | H39: 3379.72 | I39: 0 | J39: =F39+G39+H39+I39 -> 3893.567 | K39: 730.99 | L39: =J39+K39 -> 4624.557 | M39: 3184.36 | N39: 0 | O39: =M39+N39 -> 3184.36 | P39: 1253.34 | Q39: =P39+O39 -> 4437.7 | R39: =MAX(L39-Q39,0) -> 186.857 | S39: 0 | T39: 0 | U39: 0 | V39: 0 | W39: 0 | X39: 0 | Y39: =AA39+AF39 -> 0 | Z39: =AC39+AL39 -> 38.58755 | AA39: 0 | AB39: 0 | AC39: 0 | AD39: 0 | AE39: 0 | AF39: 0 | AG39: 0 | AH39: 38.58755 | AI39: 0 | AJ39: 0 | AK39: =AG39+AI39 -> 0 | AL39: =AH39+AJ39 -> 38.58755 | AM39: =AE39+AK39 -> 0 | AN39: =AF39+AL39 -> 38.58755
D40: 4 | E40: BK4 | F40: 0 | G40: 619.11774 | H40: 4351.47 | I40: 0 | J40: =F40+G40+H40+I40 -> 4970.5877 | K40: 1357.75 | L40: =J40+K40 -> 6328.3377 | M40: 3311.51 | N40: 0 | O40: =M40+N40 -> 3311.51 | P40: 2757.3058 | Q40: =P40+O40 -> 6068.8158 | R40: =MAX(L40-Q40,0) -> 259.52194 | S40: 0 | T40: 0 | U40: 0 | V40: 0 | W40: 0 | X40: 94.5442 | Y40: =AA40+AF40 -> 0 | Z40: =AC40+AL40 -> 14.229652 | AA40: 0 | AB40: 0 | AC40: 0 | AD40: 0 | AE40: 0 | AF40: 0 | AG40: 0 | AH40: 14.229652 | AI40: 0 | AJ40: 0 | AK40: =AG40+AI40 -> 0 | AL40: =AH40+AJ40 -> 14.229652 | AM40: =AE40+AK40 -> 0 | AN40: =AF40+AL40 -> 14.229652
D41: 5 | E41: BK5 | F41: 0 | G41: 190.68411 | H41: 620.69 | I41: 0 | J41: =F41+G41+H41+I41 -> 811.37411 | K41: 2717.39 | L41: =J41+K41 -> 3528.7641 | M41: 3122.9 | N41: 0 | O41: =M41+N41 -> 3122.9 | P41: 254.1371 | Q41: =P41+O41 -> 3377.0371 | R41: =MAX(L41-Q41,0) -> 151.72701 | S41: 0 | T41: 0 | U41: 0 | V41: 0 | W41: 0 | X41: 226.573 | Y41: =AA41+AF41 -> 0 | Z41: =AC41+AL41 -> 34.101 | AA41: 0 | AB41: 0 | AC41: 0 | AD41: 0 | AE41: 0 | AF41: 0 | AG41: 0 | AH41: 34.101 | AI41: 0 | AJ41: 0 | AK41: =AG41+AI41 -> 0 | AL41: =AH41+AJ41 -> 34.101 | AM41: =AE41+AK41 -> 0 | AN41: =AF41+AL41 -> 34.101
F42: =SUM(F37:F41) -> 0 | G42: =SUM(G37:G41) -> 3379.7939 | H42: =SUM(H37:H41) -> 13139.515 | I42: =SUM(I37:I41) -> 0 | J42: =SUM(J37:J41) -> 16519.309 | K42: =SUM(K37:K41) -> 6480.9329 | L42: =SUM(L37:L41) -> 23000.242 | M42: =SUM(M37:M41) -> 15534.005 | ... AN42: =SUM(AN37:AN41) -> 508.22411
A44: 2 | B44: 2 | C44: 2 | D44: 1 | E44: BK1 | F44: 0 | G44: 0 | H44: 1631.73 | I44: 0 | J44: =F44+G44+H44+I44 -> 1631.73 | K44: 2185.24 | L44: =J44+K44 -> 3816.97 | M44: 2683.865 | N44: 0 | O44: =M44+N44 -> 2683.865 | P44: 959.6 | Q44: =P44+O44 -> 3643.465 | R44: =MAX(L44-Q44,0) -> 173.505 | S44: 0 | T44: 0 | U44: 0 | V44: 0 | W44: 0 | X44: 0 | Y44: =AA44+AF44 -> 0 | Z44: =AC44+AL44 -> 2683.865 | AA44: 0 | AB44: 0 | AC44: 2683.865 | AD44: 1147.335 | AE44: 0 | AF44: 0 | AG44: 1536.53 | AH44: 0 | AI44: 0 | AJ44: 0 | AK44: =AG44+AI44 -> 1536.53 | AL44: =AH44+AJ44 -> 0 | AM44: =AE44+AK44 -> 1536.53 | AN44: =AF44+AL44 -> 0
D45: 2 | E45: BK2 | F45: 0 | G45: 587.693 | H45: 4303.24 | I45: 0 | J45: =F45+G45+H45+I45 -> 4890.933 | K45: 398.37 | L45: =J45+K45 -> 5289.303 | M45: 3231.37 | N45: 0 | O45: =M45+N45 -> 3231.37 | P45: 1844.24 | Q45: =P45+O45 -> 5075.61 | R45: =MAX(L45-Q45,0) -> 213.693 | S45: 0 | T45: 0 | U45: 0 | V45: 0 | W45: 0 | X45: 0 | Y45: =AA45+AF45 -> 0 | Z45: =AC45+AL45 -> 1215.41 | AA45: 0 | AB45: 0 | AC45: 0 | AD45: 574.5329 | AE45: 0 | AF45: 0 | AG45: 53.187054 | AH45: 1215.41 | AI45: 0 | AJ45: 0 | AK45: =AG45+AI45 -> 53.187054 | AL45: =AH45+AJ45 -> 1215.41 | AM45: =AE45+AK45 -> 53.187054 | AN45: =AF45+AL45 -> 1215.41
